<robot name = "robot">
    <link name="0">
        <inertial>
            <origin xyz="0 0 2.5" rpy="0 1.5707963267948966 0.0"/>
            <mass value="1.0" />
            <inertia ixx="100" ixy="0" ixz="0" iyy="100" iyz="0" izz="100" />
        </inertial>
        <visual>
            <origin xyz="0 0 2.5" rpy="0 1.5707963267948966 0.0"/>
            <geometry>
                <box size="0.21705524419809585 0.5964680199136614 0.43108951186840666" />
            </geometry>
            <material name="0 1 1 1">
                <color rgba="0 1 1 1"/>
            </material>
        </visual>
        <collision>
            <origin xyz="0 0 2.5" rpy="0 1.5707963267948966 0.0"/>
            <geometry>
                <box size="0.21705524419809585 0.5964680199136614 0.43108951186840666" />
            </geometry>
        </collision>
    </link>
    <joint name="0_1" type="revolute">
       <parent link="0"/>
       <child  link="1"/>
       <origin rpy="0 0 0" xyz="0.10852762209904793 -0.08940712165774557 2.586929060360666" />
       <axis xyz="0 0 1"/>
       <limit effort="0.0" lower="-3.14159" upper="3.14159" velocity="0.0"/>
    </joint>
    <link name="1">
        <inertial>
            <origin xyz="0.0712479482078152 -0.05869541643018061 0.05706857913719179" rpy="0 0.6753416169343028 -0.6890969474201154"/>
            <mass value="1.0" />
            <inertia ixx="100" ixy="0" ixz="0" iyy="100" iyz="0" izz="100" />
        </inertial>
        <visual>
            <origin xyz="0.0712479482078152 -0.05869541643018061 0.05706857913719179" rpy="0 0.6753416169343028 -0.6890969474201154"/>
            <geometry>
                <box size="0.21705524419809585 0.5964680199136614 0.43108951186840666" />
            </geometry>
            <material name="0 1 1 1">
                <color rgba="0 1 1 1"/>
            </material>
        </visual>
        <collision>
            <origin xyz="0.0712479482078152 -0.05869541643018061 0.05706857913719179" rpy="0 0.6753416169343028 -0.6890969474201154"/>
            <geometry>
                <box size="0.21705524419809585 0.5964680199136614 0.43108951186840666" />
            </geometry>
        </collision>
    </link>
    <joint name="1_2" type="revolute">
       <parent link="1"/>
       <child  link="2"/>
       <origin rpy="0 0 0" xyz="0.19195966368299155 -0.0395120288119684 0.13248240047429297" />
       <axis xyz="0 0 1"/>
       <limit effort="0.0" lower="-3.14159" upper="3.14159" velocity="0.0"/>
    </joint>
    <link name="2">
        <inertial>
            <origin xyz="0.0912170985154551 0.014496131973126268 0.05698726045980119" rpy="0 0.5584146165489419 0.1576010878876702"/>
            <mass value="1.0" />
            <inertia ixx="100" ixy="0" ixz="0" iyy="100" iyz="0" izz="100" />
        </inertial>
        <visual>
            <origin xyz="0.0912170985154551 0.014496131973126268 0.05698726045980119" rpy="0 0.5584146165489419 0.1576010878876702"/>
            <geometry>
                <box size="0.21705524419809585 0.5964680199136614 0.43108951186840666" />
            </geometry>
            <material name="0 1 1 1">
                <color rgba="0 1 1 1"/>
            </material>
        </visual>
        <collision>
            <origin xyz="0.0912170985154551 0.014496131973126268 0.05698726045980119" rpy="0 0.5584146165489419 0.1576010878876702"/>
            <geometry>
                <box size="0.21705524419809585 0.5964680199136614 0.43108951186840666" />
            </geometry>
        </collision>
    </link>
    <joint name="2_3" type="revolute">
       <parent link="2"/>
       <child  link="3"/>
       <origin rpy="0 0 0" xyz="0.20795356556308445 0.06618028616809207 0.06366704503345794" />
       <axis xyz="0 0 1"/>
       <limit effort="0.0" lower="-3.14159" upper="3.14159" velocity="0.0"/>
    </joint>
    <link name="3">
        <inertial>
            <origin xyz="0.0991008321683739 0.043876115323499325 0.005670654823610182" rpy="0 0.057158732000677316 0.4168019267881605"/>
            <mass value="1.0" />
            <inertia ixx="100" ixy="0" ixz="0" iyy="100" iyz="0" izz="100" />
        </inertial>
        <visual>
            <origin xyz="0.0991008321683739 0.043876115323499325 0.005670654823610182" rpy="0 0.057158732000677316 0.4168019267881605"/>
            <geometry>
                <box size="0.21705524419809585 0.5964680199136614 0.43108951186840666" />
            </geometry>
            <material name="0 1 1 1">
                <color rgba="0 1 1 1"/>
            </material>
        </visual>
        <collision>
            <origin xyz="0.0991008321683739 0.043876115323499325 0.005670654823610182" rpy="0 0.057158732000677316 0.4168019267881605"/>
            <geometry>
                <box size="0.21705524419809585 0.5964680199136614 0.43108951186840666" />
            </geometry>
        </collision>
    </link>
    <joint name="3_4" type="revolute">
       <parent link="3"/>
       <child  link="4"/>
       <origin rpy="0 0 0" xyz="0.21264724854632783 0.060332334129984413 -0.028952251095964592" />
       <axis xyz="0 0 1"/>
       <limit effort="0.0" lower="-3.14159" upper="3.14159" velocity="0.0"/>
    </joint>
    <link name="4">
        <inertial>
            <origin xyz="0.10282556303578137 0.014902451510089083 -0.031353871911420306" rpy="0 -0.29596710178984037 0.14392731629324879"/>
            <mass value="1.0" />
            <inertia ixx="100" ixy="0" ixz="0" iyy="100" iyz="0" izz="100" />
        </inertial>
        <visual>
            <origin xyz="0.10282556303578137 0.014902451510089083 -0.031353871911420306" rpy="0 -0.29596710178984037 0.14392731629324879"/>
            <geometry>
                <box size="0.21705524419809585 0.5964680199136614 0.43108951186840666" />
            </geometry>
            <material name="0 1 0 1">
                <color rgba="0 1 0 1"/>
            </material>
        </visual>
        <collision>
            <origin xyz="0.10282556303578137 0.014902451510089083 -0.031353871911420306" rpy="0 -0.29596710178984037 0.14392731629324879"/>
            <geometry>
                <box size="0.21705524419809585 0.5964680199136614 0.43108951186840666" />
            </geometry>
        </collision>
    </link>
    <joint name="4_5" type="revolute">
       <parent link="4"/>
       <child  link="5"/>
       <origin rpy="0 0 0" xyz="0.020772198707498406 -0.05543601076119063 -0.10559438690489673" />
       <axis xyz="0 0 1"/>
       <limit effort="0.0" lower="-3.14159" upper="3.14159" velocity="0.0"/>
    </joint>
    <link name="5">
        <inertial>
            <origin xyz="-0.24054348372959589 -0.2062006706662776 -0.21763973063874256" rpy="0 -2.4061411130138106 -2.432917154528796"/>
            <mass value="1.0" />
            <inertia ixx="100" ixy="0" ixz="0" iyy="100" iyz="0" izz="100" />
        </inertial>
        <visual>
            <origin xyz="-0.24054348372959589 -0.2062006706662776 -0.21763973063874256" rpy="0 -2.4061411130138106 -2.432917154528796"/>
            <geometry>
                <box size="0.7687572737880206 0.9334496287658063 0.7455165027236428" />
            </geometry>
            <material name="0 1 0 1">
                <color rgba="0 1 0 1"/>
            </material>
        </visual>
        <collision>
            <origin xyz="-0.24054348372959589 -0.2062006706662776 -0.21763973063874256" rpy="0 -2.4061411130138106 -2.432917154528796"/>
            <geometry>
                <box size="0.7687572737880206 0.9334496287658063 0.7455165027236428" />
            </geometry>
        </collision>
    </link>
    <joint name="5_6" type="revolute">
       <parent link="5"/>
       <child  link="6"/>
       <origin rpy="0 0 0" xyz="-0.33669587416651064 -0.5929944001281873 -0.42376468300684356" />
       <axis xyz="0 0 1"/>
       <limit effort="0.0" lower="-3.14159" upper="3.14159" velocity="0.0"/>
    </joint>
    <link name="6">
        <inertial>
            <origin xyz="-0.0823667553693371 -0.3313380390047111 -0.176572245890847" rpy="0 -2.0072670937153543 -1.8144458776888537"/>
            <mass value="1.0" />
            <inertia ixx="100" ixy="0" ixz="0" iyy="100" iyz="0" izz="100" />
        </inertial>
        <visual>
            <origin xyz="-0.0823667553693371 -0.3313380390047111 -0.176572245890847" rpy="0 -2.0072670937153543 -1.8144458776888537"/>
            <geometry>
                <box size="0.7687572737880206 0.9334496287658063 0.7455165027236428" />
            </geometry>
            <material name="0 1 0 1">
                <color rgba="0 1 0 1"/>
            </material>
        </visual>
        <collision>
            <origin xyz="-0.0823667553693371 -0.3313380390047111 -0.176572245890847" rpy="0 -2.0072670937153543 -1.8144458776888537"/>
            <geometry>
                <box size="0.7687572737880206 0.9334496287658063 0.7455165027236428" />
            </geometry>
        </collision>
    </link>
    <joint name="6_7" type="revolute">
       <parent link="6"/>
       <child  link="7"/>
       <origin rpy="0 0 0" xyz="0.06170669199237552 -0.7883899971108839 -0.22287113805902872" />
       <axis xyz="0 0 1"/>
       <limit effort="0.0" lower="-3.14159" upper="3.14159" velocity="0.0"/>
    </joint>
    <link name="7">
        <inertial>
            <origin xyz="0.1150241577515468 -0.36489733183013107 -0.03696372353126627" rpy="0 -0.31093266340126857 -1.2654323305493522"/>
            <mass value="1.0" />
            <inertia ixx="100" ixy="0" ixz="0" iyy="100" iyz="0" izz="100" />
        </inertial>
        <visual>
            <origin xyz="0.1150241577515468 -0.36489733183013107 -0.03696372353126627" rpy="0 -0.31093266340126857 -1.2654323305493522"/>
            <geometry>
                <box size="0.7687572737880206 0.9334496287658063 0.7455165027236428" />
            </geometry>
            <material name="0 1 1 1">
                <color rgba="0 1 1 1"/>
            </material>
        </visual>
        <collision>
            <origin xyz="0.1150241577515468 -0.36489733183013107 -0.03696372353126627" rpy="0 -0.31093266340126857 -1.2654323305493522"/>
            <geometry>
                <box size="0.7687572737880206 0.9334496287658063 0.7455165027236428" />
            </geometry>
        </collision>
    </link>
    <joint name="7_8" type="revolute">
       <parent link="7"/>
       <child  link="8"/>
       <origin rpy="0 0 0" xyz="0.44613332374306836 -0.6795109678363912 0.10209945210380846" />
       <axis xyz="0 0 1"/>
       <limit effort="0.0" lower="-3.14159" upper="3.14159" velocity="0.0"/>
    </joint>
    <link name="8">
        <inertial>
            <origin xyz="0.26656751955119745 -0.2532873903264869 0.11195620537700125" rpy="0 0.3976211263781417 -0.7598578803737137"/>
            <mass value="1.0" />
            <inertia ixx="100" ixy="0" ixz="0" iyy="100" iyz="0" izz="100" />
        </inertial>
        <visual>
            <origin xyz="0.26656751955119745 -0.2532873903264869 0.11195620537700125" rpy="0 0.3976211263781417 -0.7598578803737137"/>
            <geometry>
                <box size="0.7687572737880206 0.9334496287658063 0.7455165027236428" />
            </geometry>
            <material name="0 1 0 1">
                <color rgba="0 1 0 1"/>
            </material>
        </visual>
        <collision>
            <origin xyz="0.26656751955119745 -0.2532873903264869 0.11195620537700125" rpy="0 0.3976211263781417 -0.7598578803737137"/>
            <geometry>
                <box size="0.7687572737880206 0.9334496287658063 0.7455165027236428" />
            </geometry>
        </collision>
    </link>
    <joint name="8_9" type="revolute">
       <parent link="8"/>
       <child  link="9"/>
       <origin rpy="0 0 0" xyz="0.6563265576704997 -0.3462023294195 0.29341692899432736" />
       <axis xyz="0 0 1"/>
       <limit effort="0.0" lower="-3.14159" upper="3.14159" velocity="0.0"/>
    </joint>
    <link name="9">
        <inertial>
            <origin xyz="0.3406002254196118 -0.08119593416649112 0.15857377847373724" rpy="0 0.43572751654592223 -0.23402279544089394"/>
            <mass value="1.0" />
            <inertia ixx="100" ixy="0" ixz="0" iyy="100" iyz="0" izz="100" />
        </inertial>
        <visual>
            <origin xyz="0.3406002254196118 -0.08119593416649112 0.15857377847373724" rpy="0 0.43572751654592223 -0.23402279544089394"/>
            <geometry>
                <box size="0.7687572737880206 0.9334496287658063 0.7455165027236428" />
            </geometry>
            <material name="0 1 1 1">
                <color rgba="0 1 1 1"/>
            </material>
        </visual>
        <collision>
            <origin xyz="0.3406002254196118 -0.08119593416649112 0.15857377847373724" rpy="0 0.43572751654592223 -0.23402279544089394"/>
            <geometry>
                <box size="0.7687572737880206 0.9334496287658063 0.7455165027236428" />
            </geometry>
        </collision>
    </link>
    <joint name="3_10" type="revolute">
       <parent link="3"/>
       <child  link="10"/>
       <origin rpy="0 0 0" xyz="0.007100050603568761 0.10338928507837229 -0.1092233068209222" />
       <axis xyz="0 0 1"/>
       <limit effort="0.0" lower="-3.14159" upper="3.14159" velocity="0.0"/>
    </joint>
    <link name="10">
        <inertial>
            <origin xyz="-0.22273771779436854 0.14408385868517726 -0.27816305872391384" rpy="0 -2.245991458418272 2.5674161493484724"/>
            <mass value="1.0" />
            <inertia ixx="100" ixy="0" ixz="0" iyy="100" iyz="0" izz="100" />
        </inertial>
        <visual>
            <origin xyz="-0.22273771779436854 0.14408385868517726 -0.27816305872391384" rpy="0 -2.245991458418272 2.5674161493484724"/>
            <geometry>
                <box size="0.7687572737880206 0.9334496287658063 0.7455165027236428" />
            </geometry>
            <material name="0 1 0 1">
                <color rgba="0 1 0 1"/>
            </material>
        </visual>
        <collision>
            <origin xyz="-0.22273771779436854 0.14408385868517726 -0.27816305872391384" rpy="0 -2.245991458418272 2.5674161493484724"/>
            <geometry>
                <box size="0.7687572737880206 0.9334496287658063 0.7455165027236428" />
            </geometry>
        </collision>
    </link>
    <joint name="10_11" type="revolute">
       <parent link="10"/>
       <child  link="11"/>
       <origin rpy="0 0 0" xyz="-0.28783315461299935 0.21074154694529848 -0.7226628823034942" />
       <axis xyz="0 0 1"/>
       <limit effort="0.0" lower="-3.14159" upper="3.14159" velocity="0.0"/>
    </joint>
    <link name="11">
        <inertial>
            <origin xyz="-0.05509364228488363 0.05641585665631992 -0.3762032405469366" rpy="0 -1.716209155660875 2.34433763116066"/>
            <mass value="1.0" />
            <inertia ixx="100" ixy="0" ixz="0" iyy="100" iyz="0" izz="100" />
        </inertial>
        <visual>
            <origin xyz="-0.05509364228488363 0.05641585665631992 -0.3762032405469366" rpy="0 -1.716209155660875 2.34433763116066"/>
            <geometry>
                <box size="0.7687572737880206 0.9334496287658063 0.7455165027236428" />
            </geometry>
            <material name="0 1 0 1">
                <color rgba="0 1 0 1"/>
            </material>
        </visual>
        <collision>
            <origin xyz="-0.05509364228488363 0.05641585665631992 -0.3762032405469366" rpy="0 -1.716209155660875 2.34433763116066"/>
            <geometry>
                <box size="0.7687572737880206 0.9334496287658063 0.7455165027236428" />
            </geometry>
        </collision>
    </link>
    <joint name="11_12" type="revolute">
       <parent link="11"/>
       <child  link="12"/>
       <origin rpy="0 0 0" xyz="0.12227520970144284 -0.05661476317185789 -0.8118601785149279" />
       <axis xyz="0 0 1"/>
       <limit effort="0.0" lower="-3.14159" upper="3.14159" velocity="0.0"/>
    </joint>
    <link name="12">
        <inertial>
            <origin xyz="0.14092836721919144 -0.08980844449163071 -0.346151087115762" rpy="0 -1.1841588592365933 -0.5673691446172789"/>
            <mass value="1.0" />
            <inertia ixx="100" ixy="0" ixz="0" iyy="100" iyz="0" izz="100" />
        </inertial>
        <visual>
            <origin xyz="0.14092836721919144 -0.08980844449163071 -0.346151087115762" rpy="0 -1.1841588592365933 -0.5673691446172789"/>
            <geometry>
                <box size="0.7687572737880206 0.9334496287658063 0.7455165027236428" />
            </geometry>
            <material name="0 1 0 1">
                <color rgba="0 1 0 1"/>
            </material>
        </visual>
        <collision>
            <origin xyz="0.14092836721919144 -0.08980844449163071 -0.346151087115762" rpy="0 -1.1841588592365933 -0.5673691446172789"/>
            <geometry>
                <box size="0.7687572737880206 0.9334496287658063 0.7455165027236428" />
            </geometry>
        </collision>
    </link>
    <joint name="12_13" type="revolute">
       <parent link="12"/>
       <child  link="13"/>
       <origin rpy="0 0 0" xyz="0.48729101628467775 -0.3197902628759189 -0.5722959915960303" />
       <axis xyz="0 0 1"/>
       <limit effort="0.0" lower="-3.14159" upper="3.14159" velocity="0.0"/>
    </joint>
    <link name="13">
        <inertial>
            <origin xyz="0.2812976174524995 -0.1867791973050253 -0.18366305662853136" rpy="0 -0.5784207606638256 -0.5861482045252755"/>
            <mass value="1.0" />
            <inertia ixx="100" ixy="0" ixz="0" iyy="100" iyz="0" izz="100" />
        </inertial>
        <visual>
            <origin xyz="0.2812976174524995 -0.1867791973050253 -0.18366305662853136" rpy="0 -0.5784207606638256 -0.5861482045252755"/>
            <geometry>
                <box size="0.7687572737880206 0.9334496287658063 0.7455165027236428" />
            </geometry>
            <material name="0 1 0 1">
                <color rgba="0 1 0 1"/>
            </material>
        </visual>
        <collision>
            <origin xyz="0.2812976174524995 -0.1867791973050253 -0.18366305662853136" rpy="0 -0.5784207606638256 -0.5861482045252755"/>
            <geometry>
                <box size="0.7687572737880206 0.9334496287658063 0.7455165027236428" />
            </geometry>
        </collision>
    </link>
    <joint name="13_14" type="revolute">
       <parent link="13"/>
       <child  link="14"/>
       <origin rpy="0 0 0" xyz="0.6728230596465463 -0.37431968158520995 -0.19772740560891228" />
       <axis xyz="0 0 1"/>
       <limit effort="0.0" lower="-3.14159" upper="3.14159" velocity="0.0"/>
    </joint>
    <link name="14">
        <inertial>
            <origin xyz="0.3464796180007204 -0.1659635577931709 -0.012446216099887716" rpy="0 -0.03590648951497378 -0.4467064935749294"/>
            <mass value="1.0" />
            <inertia ixx="100" ixy="0" ixz="0" iyy="100" iyz="0" izz="100" />
        </inertial>
        <visual>
            <origin xyz="0.3464796180007204 -0.1659635577931709 -0.012446216099887716" rpy="0 -0.03590648951497378 -0.4467064935749294"/>
            <geometry>
                <box size="0.7687572737880206 0.9334496287658063 0.7455165027236428" />
            </geometry>
            <material name="0 1 0 1">
                <color rgba="0 1 0 1"/>
            </material>
        </visual>
        <collision>
            <origin xyz="0.3464796180007204 -0.1659635577931709 -0.012446216099887716" rpy="0 -0.03590648951497378 -0.4467064935749294"/>
            <geometry>
                <box size="0.7687572737880206 0.9334496287658063 0.7455165027236428" />
            </geometry>
        </collision>
    </link>
    <joint name="2_15" type="revolute">
       <parent link="2"/>
       <child  link="15"/>
       <origin rpy="0 0 0" xyz="-0.020352475371259997 0.18375574747660023 0.06691530003116354" />
       <axis xyz="0 0 1"/>
       <limit effort="0.0" lower="-3.14159" upper="3.14159" velocity="0.0"/>
    </joint>
    <link name="15">
        <inertial>
            <origin xyz="-0.21129146553951333 0.3205453867978065 0.018801810904981987" rpy="0 3.052841227771169 2.153585657642112"/>
            <mass value="1.0" />
            <inertia ixx="100" ixy="0" ixz="0" iyy="100" iyz="0" izz="100" />
        </inertial>
        <visual>
            <origin xyz="-0.21129146553951333 0.3205453867978065 0.018801810904981987" rpy="0 3.052841227771169 2.153585657642112"/>
            <geometry>
                <box size="0.7687572737880206 0.9334496287658063 0.7455165027236428" />
            </geometry>
            <material name="0 1 0 1">
                <color rgba="0 1 0 1"/>
            </material>
        </visual>
        <collision>
            <origin xyz="-0.21129146553951333 0.3205453867978065 0.018801810904981987" rpy="0 3.052841227771169 2.153585657642112"/>
            <geometry>
                <box size="0.7687572737880206 0.9334496287658063 0.7455165027236428" />
            </geometry>
        </collision>
    </link>
    <joint name="15_16" type="revolute">
       <parent link="15"/>
       <child  link="16"/>
       <origin rpy="0 0 0" xyz="-0.25696012053155903 0.7586068800683698 -0.10464647582428996" />
       <axis xyz="0 0 1"/>
       <limit effort="0.0" lower="-3.14159" upper="3.14159" velocity="0.0"/>
    </joint>
    <link name="16">
        <inertial>
            <origin xyz="-0.03837715484285749 0.3681201857349625 -0.10373841786494271" rpy="0 -1.9251248649473474 1.6746727862098367"/>
            <mass value="1.0" />
            <inertia ixx="100" ixy="0" ixz="0" iyy="100" iyz="0" izz="100" />
        </inertial>
        <visual>
            <origin xyz="-0.03837715484285749 0.3681201857349625 -0.10373841786494271" rpy="0 -1.9251248649473474 1.6746727862098367"/>
            <geometry>
                <box size="0.7687572737880206 0.9334496287658063 0.7455165027236428" />
            </geometry>
            <material name="0 1 1 1">
                <color rgba="0 1 1 1"/>
            </material>
        </visual>
        <collision>
            <origin xyz="-0.03837715484285749 0.3681201857349625 -0.10373841786494271" rpy="0 -1.9251248649473474 1.6746727862098367"/>
            <geometry>
                <box size="0.7687572737880206 0.9334496287658063 0.7455165027236428" />
            </geometry>
        </collision>
    </link>
    <joint name="16_17" type="revolute">
       <parent link="16"/>
       <child  link="17"/>
       <origin rpy="0 0 0" xyz="0.15821816561800273 0.7108325851802122 -0.38456353566915397" />
       <axis xyz="0 0 1"/>
       <limit effort="0.0" lower="-3.14159" upper="3.14159" velocity="0.0"/>
    </joint>
    <link name="17">
        <inertial>
            <origin xyz="0.1558947603867329 0.27176164350115434 -0.22268670662168416" rpy="0 -0.9600279718125019 1.049980816618299"/>
            <mass value="1.0" />
            <inertia ixx="100" ixy="0" ixz="0" iyy="100" iyz="0" izz="100" />
        </inertial>
        <visual>
            <origin xyz="0.1558947603867329 0.27176164350115434 -0.22268670662168416" rpy="0 -0.9600279718125019 1.049980816618299"/>
            <geometry>
                <box size="0.7687572737880206 0.9334496287658063 0.7455165027236428" />
            </geometry>
            <material name="0 1 1 1">
                <color rgba="0 1 1 1"/>
            </material>
        </visual>
        <collision>
            <origin xyz="0.1558947603867329 0.27176164350115434 -0.22268670662168416" rpy="0 -0.9600279718125019 1.049980816618299"/>
            <geometry>
                <box size="0.7687572737880206 0.9334496287658063 0.7455165027236428" />
            </geometry>
        </collision>
    </link>
    <joint name="17_18" type="revolute">
       <parent link="17"/>
       <child  link="18"/>
       <origin rpy="0 0 0" xyz="0.5100876463192237 0.37221062965817575 -0.5156181565538533" />
       <axis xyz="0 0 1"/>
       <limit effort="0.0" lower="-3.14159" upper="3.14159" velocity="0.0"/>
    </joint>
    <link name="18">
        <inertial>
            <origin xyz="0.289372933388562 0.082066068898133 -0.23932279928624256" rpy="0 -0.6910122708760099 0.27634354832478386"/>
            <mass value="1.0" />
            <inertia ixx="100" ixy="0" ixz="0" iyy="100" iyz="0" izz="100" />
        </inertial>
        <visual>
            <origin xyz="0.289372933388562 0.082066068898133 -0.23932279928624256" rpy="0 -0.6910122708760099 0.27634354832478386"/>
            <geometry>
                <box size="0.7687572737880206 0.9334496287658063 0.7455165027236428" />
            </geometry>
            <material name="0 1 0 1">
                <color rgba="0 1 0 1"/>
            </material>
        </visual>
        <collision>
            <origin xyz="0.289372933388562 0.082066068898133 -0.23932279928624256" rpy="0 -0.6910122708760099 0.27634354832478386"/>
            <geometry>
                <box size="0.7687572737880206 0.9334496287658063 0.7455165027236428" />
            </geometry>
        </collision>
    </link>
    <joint name="18_19" type="revolute">
       <parent link="18"/>
       <child  link="19"/>
       <origin rpy="0 0 0" xyz="0.6815709182014662 0.015014087730699004 -0.4054505054259102" />
       <axis xyz="0 0 1"/>
       <limit effort="0.0" lower="-3.14159" upper="3.14159" velocity="0.0"/>
    </joint>
    <link name="19">
        <inertial>
            <origin xyz="0.34963022572910596 -0.05977440022374732 -0.14809680224435337" rpy="0 -0.4006683258749013 -0.1693275372708944"/>
            <mass value="1.0" />
            <inertia ixx="100" ixy="0" ixz="0" iyy="100" iyz="0" izz="100" />
        </inertial>
        <visual>
            <origin xyz="0.34963022572910596 -0.05977440022374732 -0.14809680224435337" rpy="0 -0.4006683258749013 -0.1693275372708944"/>
            <geometry>
                <box size="0.7687572737880206 0.9334496287658063 0.7455165027236428" />
            </geometry>
            <material name="0 1 1 1">
                <color rgba="0 1 1 1"/>
            </material>
        </visual>
        <collision>
            <origin xyz="0.34963022572910596 -0.05977440022374732 -0.14809680224435337" rpy="0 -0.4006683258749013 -0.1693275372708944"/>
            <geometry>
                <box size="0.7687572737880206 0.9334496287658063 0.7455165027236428" />
            </geometry>
        </collision>
    </link>
    <joint name="1_20" type="revolute">
       <parent link="1"/>
       <child  link="20"/>
       <origin rpy="0 0 0" xyz="-0.08085844585908139 0.06590344401238946 0.2496961045035942" />
       <axis xyz="0 0 1"/>
       <limit effort="0.0" lower="-3.14159" upper="3.14159" velocity="0.0"/>
    </joint>
    <link name="20">
        <inertial>
            <origin xyz="-0.21240651281188885 0.17399406257242483 0.26899159095617364" rpy="0 2.2391881784854673 2.4552798959342983"/>
            <mass value="1.0" />
            <inertia ixx="100" ixy="0" ixz="0" iyy="100" iyz="0" izz="100" />
        </inertial>
        <visual>
            <origin xyz="-0.21240651281188885 0.17399406257242483 0.26899159095617364" rpy="0 2.2391881784854673 2.4552798959342983"/>
            <geometry>
                <box size="0.7687572737880206 0.9334496287658063 0.7455165027236428" />
            </geometry>
            <material name="0 1 1 1">
                <color rgba="0 1 1 1"/>
            </material>
        </visual>
        <collision>
            <origin xyz="-0.21240651281188885 0.17399406257242483 0.26899159095617364" rpy="0 2.2391881784854673 2.4552798959342983"/>
            <geometry>
                <box size="0.7687572737880206 0.9334496287658063 0.7455165027236428" />
            </geometry>
        </collision>
    </link>
    <joint name="20_21" type="revolute">
       <parent link="20"/>
       <child  link="21"/>
       <origin rpy="0 0 0" xyz="-0.2599491405637826 0.5320830875643646 0.5490866238196112" />
       <axis xyz="0 0 1"/>
       <limit effort="0.0" lower="-3.14159" upper="3.14159" velocity="0.0"/>
    </joint>
    <link name="21">
        <inertial>
            <origin xyz="-0.03997885027396739 0.30111897873237525 0.23553341308281603" rpy="0 1.7389313360230558 1.702791986501816"/>
            <mass value="1.0" />
            <inertia ixx="100" ixy="0" ixz="0" iyy="100" iyz="0" izz="100" />
        </inertial>
        <visual>
            <origin xyz="-0.03997885027396739 0.30111897873237525 0.23553341308281603" rpy="0 1.7389313360230558 1.702791986501816"/>
            <geometry>
                <box size="0.7687572737880206 0.9334496287658063 0.7455165027236428" />
            </geometry>
            <material name="0 1 1 1">
                <color rgba="0 1 1 1"/>
            </material>
        </visual>
        <collision>
            <origin xyz="-0.03997885027396739 0.30111897873237525 0.23553341308281603" rpy="0 1.7389313360230558 1.702791986501816"/>
            <geometry>
                <box size="0.7687572737880206 0.9334496287658063 0.7455165027236428" />
            </geometry>
        </collision>
    </link>
    <joint name="21_22" type="revolute">
       <parent link="21"/>
       <child  link="22"/>
       <origin rpy="0 0 0" xyz="0.15481316957445052 0.7307892802711916 0.3465691033625019" />
       <axis xyz="0 0 1"/>
       <limit effort="0.0" lower="-3.14159" upper="3.14159" velocity="0.0"/>
    </joint>
    <link name="22">
        <inertial>
            <origin xyz="0.15448939492641345 0.3407711720132897 0.08806231702866467" rpy="0 0.5180849533144019 1.1451581244884086"/>
            <mass value="1.0" />
            <inertia ixx="100" ixy="0" ixz="0" iyy="100" iyz="0" izz="100" />
        </inertial>
        <visual>
            <origin xyz="0.15448939492641345 0.3407711720132897 0.08806231702866467" rpy="0 0.5180849533144019 1.1451581244884086"/>
            <geometry>
                <box size="0.7687572737880206 0.9334496287658063 0.7455165027236428" />
            </geometry>
            <material name="0 1 0 1">
                <color rgba="0 1 0 1"/>
            </material>
        </visual>
        <collision>
            <origin xyz="0.15448939492641345 0.3407711720132897 0.08806231702866467" rpy="0 0.5180849533144019 1.1451581244884086"/>
            <geometry>
                <box size="0.7687572737880206 0.9334496287658063 0.7455165027236428" />
            </geometry>
        </collision>
    </link>
    <joint name="22_23" type="revolute">
       <parent link="22"/>
       <child  link="23"/>
       <origin rpy="0 0 0" xyz="0.5079776253502108 0.6378064590536114 -0.00373982375178444" />
       <axis xyz="0 0 1"/>
       <limit effort="0.0" lower="-3.14159" upper="3.14159" velocity="0.0"/>
    </joint>
    <link name="23">
        <inertial>
            <origin xyz="0.2886277146271839 0.24253315579784007 -0.07495763595743252" rpy="0 -0.254090339612871 0.6988342423906289"/>
            <mass value="1.0" />
            <inertia ixx="100" ixy="0" ixz="0" iyy="100" iyz="0" izz="100" />
        </inertial>
        <visual>
            <origin xyz="0.2886277146271839 0.24253315579784007 -0.07495763595743252" rpy="0 -0.254090339612871 0.6988342423906289"/>
            <geometry>
                <box size="0.7687572737880206 0.9334496287658063 0.7455165027236428" />
            </geometry>
            <material name="0 1 0 1">
                <color rgba="0 1 0 1"/>
            </material>
        </visual>
        <collision>
            <origin xyz="0.2886277146271839 0.24253315579784007 -0.07495763595743252" rpy="0 -0.254090339612871 0.6988342423906289"/>
            <geometry>
                <box size="0.7687572737880206 0.9334496287658063 0.7455165027236428" />
            </geometry>
        </collision>
    </link>
    <joint name="23_24" type="revolute">
       <parent link="23"/>
       <child  link="24"/>
       <origin rpy="0 0 0" xyz="0.6807724097409633 0.3378598848297977 -0.227620093577169" />
       <axis xyz="0 0 1"/>
       <limit effort="0.0" lower="-3.14159" upper="3.14159" velocity="0.0"/>
    </joint>
    <link name="24">
        <inertial>
            <origin xyz="0.34934150377986173 0.08492167122336598 -0.13599911762196412" rpy="0 -0.37124951259094074 0.23846529703527897"/>
            <mass value="1.0" />
            <inertia ixx="100" ixy="0" ixz="0" iyy="100" iyz="0" izz="100" />
        </inertial>
        <visual>
            <origin xyz="0.34934150377986173 0.08492167122336598 -0.13599911762196412" rpy="0 -0.37124951259094074 0.23846529703527897"/>
            <geometry>
                <box size="0.7687572737880206 0.9334496287658063 0.7455165027236428" />
            </geometry>
            <material name="0 1 0 1">
                <color rgba="0 1 0 1"/>
            </material>
        </visual>
        <collision>
            <origin xyz="0.34934150377986173 0.08492167122336598 -0.13599911762196412" rpy="0 -0.37124951259094074 0.23846529703527897"/>
            <geometry>
                <box size="0.7687572737880206 0.9334496287658063 0.7455165027236428" />
            </geometry>
        </collision>
    </link>
    <joint name="0_25" type="revolute">
       <parent link="0"/>
       <child  link="25"/>
       <origin rpy="0 0 0" xyz="-0.06595253054611269 -0.2982340099568307 2.3087762169187442" />
       <axis xyz="0 0 1"/>
       <limit effort="0.0" lower="-3.14159" upper="3.14159" velocity="0.0"/>
    </joint>
    <link name="25">
        <inertial>
            <origin xyz="-0.07034825798477796 -0.31811126727895606 -0.20396882293424431" rpy="0 -1.9029179303718278 -1.788437136122657"/>
            <mass value="1.0" />
            <inertia ixx="100" ixy="0" ixz="0" iyy="100" iyz="0" izz="100" />
        </inertial>
        <visual>
            <origin xyz="-0.07034825798477796 -0.31811126727895606 -0.20396882293424431" rpy="0 -1.9029179303718278 -1.788437136122657"/>
            <geometry>
                <box size="0.7687572737880206 0.9334496287658063 0.7455165027236428" />
            </geometry>
            <material name="0 1 0 1">
                <color rgba="0 1 0 1"/>
            </material>
        </visual>
        <collision>
            <origin xyz="-0.07034825798477796 -0.31811126727895606 -0.20396882293424431" rpy="0 -1.9029179303718278 -1.788437136122657"/>
            <geometry>
                <box size="0.7687572737880206 0.9334496287658063 0.7455165027236428" />
            </geometry>
        </collision>
    </link>
    <joint name="25_26" type="revolute">
       <parent link="25"/>
       <child  link="26"/>
       <origin rpy="0 0 0" xyz="0.08869205262712171 -0.7667481747148869 -0.28348435817893974" />
       <axis xyz="0 0 1"/>
       <limit effort="0.0" lower="-3.14159" upper="3.14159" velocity="0.0"/>
    </joint>
    <link name="26">
        <inertial>
            <origin xyz="0.1266745968742742 -0.35733644617338556 -0.06333361858770342" rpy="0 -0.4636243690314129 -1.23012115408074"/>
            <mass value="1.0" />
            <inertia ixx="100" ixy="0" ixz="0" iyy="100" iyz="0" izz="100" />
        </inertial>
        <visual>
            <origin xyz="0.1266745968742742 -0.35733644617338556 -0.06333361858770342" rpy="0 -0.4636243690314129 -1.23012115408074"/>
            <geometry>
                <box size="0.7687572737880206 0.9334496287658063 0.7455165027236428" />
            </geometry>
            <material name="0 1 1 1">
                <color rgba="0 1 1 1"/>
            </material>
        </visual>
        <collision>
            <origin xyz="0.1266745968742742 -0.35733644617338556 -0.06333361858770342" rpy="0 -0.4636243690314129 -1.23012115408074"/>
            <geometry>
                <box size="0.7687572737880206 0.9334496287658063 0.7455165027236428" />
            </geometry>
        </collision>
    </link>
    <joint name="26_27" type="revolute">
       <parent link="26"/>
       <child  link="27"/>
       <origin rpy="0 0 0" xyz="0.4649107896913597 -0.6713259573388737 0.051911540164482316" />
       <axis xyz="0 0 1"/>
       <limit effort="0.0" lower="-3.14159" upper="3.14159" velocity="0.0"/>
    </joint>
    <link name="27">
        <inertial>
            <origin xyz="0.2733137204890337 -0.2537210485265301 0.09312452001238977" rpy="0 0.3283872626865643 -0.7482399816531805"/>
            <mass value="1.0" />
            <inertia ixx="100" ixy="0" ixz="0" iyy="100" iyz="0" izz="100" />
        </inertial>
        <visual>
            <origin xyz="0.2733137204890337 -0.2537210485265301 0.09312452001238977" rpy="0 0.3283872626865643 -0.7482399816531805"/>
            <geometry>
                <box size="0.7687572737880206 0.9334496287658063 0.7455165027236428" />
            </geometry>
            <material name="0 1 0 1">
                <color rgba="0 1 0 1"/>
            </material>
        </visual>
        <collision>
            <origin xyz="0.2733137204890337 -0.2537210485265301 0.09312452001238977" rpy="0 0.3283872626865643 -0.7482399816531805"/>
            <geometry>
                <box size="0.7687572737880206 0.9334496287658063 0.7455165027236428" />
            </geometry>
        </collision>
    </link>
    <joint name="27_28" type="revolute">
       <parent link="27"/>
       <child  link="28"/>
       <origin rpy="0 0 0" xyz="0.6639682710463987 -0.35286632462805256 0.26300936291581883" />
       <axis xyz="0 0 1"/>
       <limit effort="0.0" lower="-3.14159" upper="3.14159" velocity="0.0"/>
    </joint>
    <link name="28">
        <inertial>
            <origin xyz="0.34331501830777583 -0.0871308480378892 0.1492981916334797" rpy="0 0.4102027700167269 -0.24854507242567683"/>
            <mass value="1.0" />
            <inertia ixx="100" ixy="0" ixz="0" iyy="100" iyz="0" izz="100" />
        </inertial>
        <visual>
            <origin xyz="0.34331501830777583 -0.0871308480378892 0.1492981916334797" rpy="0 0.4102027700167269 -0.24854507242567683"/>
            <geometry>
                <box size="0.7687572737880206 0.9334496287658063 0.7455165027236428" />
            </geometry>
            <material name="0 1 0 1">
                <color rgba="0 1 0 1"/>
            </material>
        </visual>
        <collision>
            <origin xyz="0.34331501830777583 -0.0871308480378892 0.1492981916334797" rpy="0 0.4102027700167269 -0.24854507242567683"/>
            <geometry>
                <box size="0.7687572737880206 0.9334496287658063 0.7455165027236428" />
            </geometry>
        </collision>
    </link>
    <joint name="28_29" type="revolute">
       <parent link="28"/>
       <child  link="29"/>
       <origin rpy="0 0 0" xyz="0.7346315878577433 -0.056982232002740794 0.25666021369316977" />
       <axis xyz="0 0 1"/>
       <limit effort="0.0" lower="-3.14159" upper="3.14159" velocity="0.0"/>
    </joint>
    <link name="29">
        <inertial>
            <origin xyz="0.36966153445859806 0.028480224280237054 0.10142072405164317" rpy="0 0.26777208043264383 0.07689215844801371"/>
            <mass value="1.0" />
            <inertia ixx="100" ixy="0" ixz="0" iyy="100" iyz="0" izz="100" />
        </inertial>
        <visual>
            <origin xyz="0.36966153445859806 0.028480224280237054 0.10142072405164317" rpy="0 0.26777208043264383 0.07689215844801371"/>
            <geometry>
                <box size="0.7687572737880206 0.9334496287658063 0.7455165027236428" />
            </geometry>
            <material name="0 1 1 1">
                <color rgba="0 1 1 1"/>
            </material>
        </visual>
        <collision>
            <origin xyz="0.36966153445859806 0.028480224280237054 0.10142072405164317" rpy="0 0.26777208043264383 0.07689215844801371"/>
            <geometry>
                <box size="0.7687572737880206 0.9334496287658063 0.7455165027236428" />
            </geometry>
        </collision>
    </link>
</robot>