<robot name = "robot">
    <link name="0">
        <inertial>
            <origin xyz="0 0 2.5" rpy="0 0.0 1.5707963267948966"/>
            <mass value="1.0" />
            <inertia ixx="100" ixy="0" ixz="0" iyy="100" iyz="0" izz="100" />
        </inertial>
        <visual>
            <origin xyz="0 0 2.5" rpy="0 0.0 1.5707963267948966"/>
            <geometry>
                <box size="0.6840596376156676 0.7079142910708802 0.9407070144918339" />
            </geometry>
            <material name="0 1 1 1">
                <color rgba="0 1 1 1"/>
            </material>
        </visual>
        <collision>
            <origin xyz="0 0 2.5" rpy="0 0.0 1.5707963267948966"/>
            <geometry>
                <box size="0.6840596376156676 0.7079142910708802 0.9407070144918339" />
            </geometry>
        </collision>
    </link>
    <joint name="0_1" type="revolute">
       <parent link="0"/>
       <child  link="1"/>
       <origin rpy="0 0 0" xyz="0.3420298188078338 0.34273412340578147 2.1121621579335277" />
       <axis xyz="0 0 1"/>
       <limit effort="0.0" lower="-3.14159" upper="3.14159" velocity="0.0"/>
    </joint>
    <link name="1">
        <inertial>
            <origin xyz="0.18856944536791628 0.1889577458028549 -0.21382453443994612" rpy="0 0.786426699373383 -0.8480780440152362"/>
            <mass value="1.0" />
            <inertia ixx="100" ixy="0" ixz="0" iyy="100" iyz="0" izz="100" />
        </inertial>
        <visual>
            <origin xyz="0.18856944536791628 0.1889577458028549 -0.21382453443994612" rpy="0 0.786426699373383 -0.8480780440152362"/>
            <geometry>
                <box size="0.6840596376156676 0.7079142910708802 0.9407070144918339" />
            </geometry>
            <material name="0 1 1 1">
                <color rgba="0 1 1 1"/>
            </material>
        </visual>
        <collision>
            <origin xyz="0.18856944536791628 0.1889577458028549 -0.21382453443994612" rpy="0 0.786426699373383 -0.8480780440152362"/>
            <geometry>
                <box size="0.6840596376156676 0.7079142910708802 0.9407070144918339" />
            </geometry>
        </collision>
    </link>
    <joint name="1_2" type="revolute">
       <parent link="1"/>
       <child  link="2"/>
       <origin rpy="0 0 0" xyz="0.10718776979190486 0.710309803877402 -0.3719775022709223" />
       <axis xyz="0 0 1"/>
       <limit effort="0.0" lower="-3.14159" upper="3.14159" velocity="0.0"/>
    </joint>
    <link name="2">
        <inertial>
            <origin xyz="-0.050530292990085525 0.32371012342803485 -0.09819797571366824" rpy="0 1.7256440549120553 -2.0460363934601737"/>
            <mass value="1.0" />
            <inertia ixx="100" ixy="0" ixz="0" iyy="100" iyz="0" izz="100" />
        </inertial>
        <visual>
            <origin xyz="-0.050530292990085525 0.32371012342803485 -0.09819797571366824" rpy="0 1.7256440549120553 -2.0460363934601737"/>
            <geometry>
                <box size="0.6840596376156676 0.7079142910708802 0.9407070144918339" />
            </geometry>
            <material name="0 1 1 1">
                <color rgba="0 1 1 1"/>
            </material>
        </visual>
        <collision>
            <origin xyz="-0.050530292990085525 0.32371012342803485 -0.09819797571366824" rpy="0 1.7256440549120553 -2.0460363934601737"/>
            <geometry>
                <box size="0.6840596376156676 0.7079142910708802 0.9407070144918339" />
            </geometry>
        </collision>
    </link>
    <joint name="2_3" type="revolute">
       <parent link="2"/>
       <child  link="3"/>
       <origin rpy="0 0 0" xyz="-0.48043344926331516 0.691591587892214 0.14443115778483945" />
       <axis xyz="0 0 1"/>
       <limit effort="0.0" lower="-3.14159" upper="3.14159" velocity="0.0"/>
    </joint>
    <link name="3">
        <inertial>
            <origin xyz="-0.23883730930442984 0.20438049321916346 0.1347952173833747" rpy="0 2.4337808346670595 2.627775521702613"/>
            <mass value="1.0" />
            <inertia ixx="100" ixy="0" ixz="0" iyy="100" iyz="0" izz="100" />
        </inertial>
        <visual>
            <origin xyz="-0.23883730930442984 0.20438049321916346 0.1347952173833747" rpy="0 2.4337808346670595 2.627775521702613"/>
            <geometry>
                <box size="0.6840596376156676 0.7079142910708802 0.9407070144918339" />
            </geometry>
            <material name="0 1 1 1">
                <color rgba="0 1 1 1"/>
            </material>
        </visual>
        <collision>
            <origin xyz="-0.23883730930442984 0.20438049321916346 0.1347952173833747" rpy="0 2.4337808346670595 2.627775521702613"/>
            <geometry>
                <box size="0.6840596376156676 0.7079142910708802 0.9407070144918339" />
            </geometry>
        </collision>
    </link>
    <joint name="3_4" type="revolute">
       <parent link="3"/>
       <child  link="4"/>
       <origin rpy="0 0 0" xyz="-0.24748042853640456 0.38333349662264216 0.09721184253098573" />
       <axis xyz="0 0 1"/>
       <limit effort="0.0" lower="-3.14159" upper="3.14159" velocity="0.0"/>
    </joint>
    <link name="4">
        <inertial>
            <origin xyz="-0.018497208972535154 0.382978761645599 -0.08043248275066653" rpy="0 1.6190570868443699 -1.7968380039078944"/>
            <mass value="1.0" />
            <inertia ixx="100" ixy="0" ixz="0" iyy="100" iyz="0" izz="100" />
        </inertial>
        <visual>
            <origin xyz="-0.018497208972535154 0.382978761645599 -0.08043248275066653" rpy="0 1.6190570868443699 -1.7968380039078944"/>
            <geometry>
                <box size="0.7835413528150419 0.5573811368381423 0.4818255872887541" />
            </geometry>
            <material name="0 1 0 1">
                <color rgba="0 1 0 1"/>
            </material>
        </visual>
        <collision>
            <origin xyz="-0.018497208972535154 0.382978761645599 -0.08043248275066653" rpy="0 1.6190570868443699 -1.7968380039078944"/>
            <geometry>
                <box size="0.7835413528150419 0.5573811368381423 0.4818255872887541" />
            </geometry>
        </collision>
    </link>
    <joint name="4_5" type="revolute">
       <parent link="4"/>
       <child  link="5"/>
       <origin rpy="0 0 0" xyz="-0.10230557741204549 0.7840738466797083 -0.059584475539899956" />
       <axis xyz="0 0 1"/>
       <limit effort="0.0" lower="-3.14159" upper="3.14159" velocity="0.0"/>
    </joint>
    <link name="5">
        <inertial>
            <origin xyz="-0.08002600450893992 0.38299322228925614 0.019907113694205752" rpy="0 1.7767815841421737 2.8977832155672143"/>
            <mass value="1.0" />
            <inertia ixx="100" ixy="0" ixz="0" iyy="100" iyz="0" izz="100" />
        </inertial>
        <visual>
            <origin xyz="-0.08002600450893992 0.38299322228925614 0.019907113694205752" rpy="0 1.7767815841421737 2.8977832155672143"/>
            <geometry>
                <box size="0.7835413528150419 0.5573811368381423 0.4818255872887541" />
            </geometry>
            <material name="0 1 0 1">
                <color rgba="0 1 0 1"/>
            </material>
        </visual>
        <collision>
            <origin xyz="-0.08002600450893992 0.38299322228925614 0.019907113694205752" rpy="0 1.7767815841421737 2.8977832155672143"/>
            <geometry>
                <box size="0.7835413528150419 0.5573811368381423 0.4818255872887541" />
            </geometry>
        </collision>
    </link>
    <joint name="5_6" type="revolute">
       <parent link="5"/>
       <child  link="6"/>
       <origin rpy="0 0 0" xyz="-0.22277787571263655 0.7476837127424416 0.13978460894253497" />
       <axis xyz="0 0 1"/>
       <limit effort="0.0" lower="-3.14159" upper="3.14159" velocity="0.0"/>
    </joint>
    <link name="6">
        <inertial>
            <origin xyz="-0.13654796626665194 0.34884127520200786 0.11466769604681513" rpy="0 1.9438955613460016 2.44307280301956"/>
            <mass value="1.0" />
            <inertia ixx="100" ixy="0" ixz="0" iyy="100" iyz="0" izz="100" />
        </inertial>
        <visual>
            <origin xyz="-0.13654796626665194 0.34884127520200786 0.11466769604681513" rpy="0 1.9438955613460016 2.44307280301956"/>
            <geometry>
                <box size="0.7835413528150419 0.5573811368381423 0.4818255872887541" />
            </geometry>
            <material name="0 1 1 1">
                <color rgba="0 1 1 1"/>
            </material>
        </visual>
        <collision>
            <origin xyz="-0.13654796626665194 0.34884127520200786 0.11466769604681513" rpy="0 1.9438955613460016 2.44307280301956"/>
            <geometry>
                <box size="0.7835413528150419 0.5573811368381423 0.4818255872887541" />
            </geometry>
        </collision>
    </link>
    <joint name="2_7" type="revolute">
       <parent link="2"/>
       <child  link="7"/>
       <origin rpy="0 0 0" xyz="0.04931999005817721 0.3808543565143046 -0.3030905961834568" />
       <axis xyz="0 0 1"/>
       <limit effort="0.0" lower="-3.14159" upper="3.14159" velocity="0.0"/>
    </joint>
    <link name="7">
        <inertial>
            <origin xyz="0.16647410091176856 0.09527298806685565 -0.3416045877373978" rpy="0 0.5198021577558548 -1.117336144907831"/>
            <mass value="1.0" />
            <inertia ixx="100" ixy="0" ixz="0" iyy="100" iyz="0" izz="100" />
        </inertial>
        <visual>
            <origin xyz="0.16647410091176856 0.09527298806685565 -0.3416045877373978" rpy="0 0.5198021577558548 -1.117336144907831"/>
            <geometry>
                <box size="0.7835413528150419 0.5573811368381423 0.4818255872887541" />
            </geometry>
            <material name="0 1 1 1">
                <color rgba="0 1 1 1"/>
            </material>
        </visual>
        <collision>
            <origin xyz="0.16647410091176856 0.09527298806685565 -0.3416045877373978" rpy="0 0.5198021577558548 -1.117336144907831"/>
            <geometry>
                <box size="0.7835413528150419 0.5573811368381423 0.4818255872887541" />
            </geometry>
        </collision>
    </link>
    <joint name="7_8" type="revolute">
       <parent link="7"/>
       <child  link="8"/>
       <origin rpy="0 0 0" xyz="0.2793102718354171 0.2870830117271478 -0.6824245089914274" />
       <axis xyz="0 0 1"/>
       <limit effort="0.0" lower="-3.14159" upper="3.14159" velocity="0.0"/>
    </joint>
    <link name="8">
        <inertial>
            <origin xyz="0.10860342273206282 0.18461478188515706 -0.3280349703510027" rpy="0 1.0390461338474204 -1.2510817219853168"/>
            <mass value="1.0" />
            <inertia ixx="100" ixy="0" ixz="0" iyy="100" iyz="0" izz="100" />
        </inertial>
        <visual>
            <origin xyz="0.10860342273206282 0.18461478188515706 -0.3280349703510027" rpy="0 1.0390461338474204 -1.2510817219853168"/>
            <geometry>
                <box size="0.7835413528150419 0.5573811368381423 0.4818255872887541" />
            </geometry>
            <material name="0 1 1 1">
                <color rgba="0 1 1 1"/>
            </material>
        </visual>
        <collision>
            <origin xyz="0.10860342273206282 0.18461478188515706 -0.3280349703510027" rpy="0 1.0390461338474204 -1.2510817219853168"/>
            <geometry>
                <box size="0.7835413528150419 0.5573811368381423 0.4818255872887541" />
            </geometry>
        </collision>
    </link>
    <joint name="8_9" type="revolute">
       <parent link="8"/>
       <child  link="9"/>
       <origin rpy="0 0 0" xyz="0.15677990579920004 0.46398716671267903 -0.6227470248109532" />
       <axis xyz="0 0 1"/>
       <limit effort="0.0" lower="-3.14159" upper="3.14159" velocity="0.0"/>
    </joint>
    <link name="9">
        <inertial>
            <origin xyz="0.04615473797429208 0.2676484126290041 -0.28234434698166944" rpy="0 1.400030419576647 -1.4087598415735567"/>
            <mass value="1.0" />
            <inertia ixx="100" ixy="0" ixz="0" iyy="100" iyz="0" izz="100" />
        </inertial>
        <visual>
            <origin xyz="0.04615473797429208 0.2676484126290041 -0.28234434698166944" rpy="0 1.400030419576647 -1.4087598415735567"/>
            <geometry>
                <box size="0.7835413528150419 0.5573811368381423 0.4818255872887541" />
            </geometry>
            <material name="0 1 0 1">
                <color rgba="0 1 0 1"/>
            </material>
        </visual>
        <collision>
            <origin xyz="0.04615473797429208 0.2676484126290041 -0.28234434698166944" rpy="0 1.400030419576647 -1.4087598415735567"/>
            <geometry>
                <box size="0.7835413528150419 0.5573811368381423 0.4818255872887541" />
            </geometry>
        </collision>
    </link>
    <joint name="1_10" type="revolute">
       <parent link="1"/>
       <child  link="10"/>
       <origin rpy="0 0 0" xyz="0.3240554874734851 0.09412867765799768 -0.33515253107528875" />
       <axis xyz="0 0 1"/>
       <limit effort="0.0" lower="-3.14159" upper="3.14159" velocity="0.0"/>
    </joint>
    <link name="10">
        <inertial>
            <origin xyz="0.25878720151530504 -0.18112972219226914 -0.23174440869896898" rpy="0 -0.6106706737138256 -0.7303243509562637"/>
            <mass value="1.0" />
            <inertia ixx="100" ixy="0" ixz="0" iyy="100" iyz="0" izz="100" />
        </inertial>
        <visual>
            <origin xyz="0.25878720151530504 -0.18112972219226914 -0.23174440869896898" rpy="0 -0.6106706737138256 -0.7303243509562637"/>
            <geometry>
                <box size="0.7835413528150419 0.5573811368381423 0.4818255872887541" />
            </geometry>
            <material name="0 1 0 1">
                <color rgba="0 1 0 1"/>
            </material>
        </visual>
        <collision>
            <origin xyz="0.25878720151530504 -0.18112972219226914 -0.23174440869896898" rpy="0 -0.6106706737138256 -0.7303243509562637"/>
            <geometry>
                <box size="0.7835413528150419 0.5573811368381423 0.4818255872887541" />
            </geometry>
        </collision>
    </link>
    <joint name="10_11" type="revolute">
       <parent link="10"/>
       <child  link="11"/>
       <origin rpy="0 0 0" xyz="0.4806786509692844 -0.32134808814354243 -0.5366660349601625" />
       <axis xyz="0 0 1"/>
       <limit effort="0.0" lower="-3.14159" upper="3.14159" velocity="0.0"/>
    </joint>
    <link name="11">
        <inertial>
            <origin xyz="0.21606462642706162 -0.13653626100521896 -0.29691444816723805" rpy="0 -0.5635623486905865 -0.9417206762572867"/>
            <mass value="1.0" />
            <inertia ixx="100" ixy="0" ixz="0" iyy="100" iyz="0" izz="100" />
        </inertial>
        <visual>
            <origin xyz="0.21606462642706162 -0.13653626100521896 -0.29691444816723805" rpy="0 -0.5635623486905865 -0.9417206762572867"/>
            <geometry>
                <box size="0.7835413528150419 0.5573811368381423 0.4818255872887541" />
            </geometry>
            <material name="0 1 0 1">
                <color rgba="0 1 0 1"/>
            </material>
        </visual>
        <collision>
            <origin xyz="0.21606462642706162 -0.13653626100521896 -0.29691444816723805" rpy="0 -0.5635623486905865 -0.9417206762572867"/>
            <geometry>
                <box size="0.7835413528150419 0.5573811368381423 0.4818255872887541" />
            </geometry>
        </collision>
    </link>
    <joint name="11_12" type="revolute">
       <parent link="11"/>
       <child  link="12"/>
       <origin rpy="0 0 0" xyz="0.3865816646491185 -0.20762531444524515 -0.6570698054928462" />
       <axis xyz="0 0 1"/>
       <limit effort="0.0" lower="-3.14159" upper="3.14159" velocity="0.0"/>
    </joint>
    <link name="12">
        <inertial>
            <origin xyz="0.165039395065222 -0.06880540793948373 -0.3485858241632802" rpy="0 -0.3949924188976809 -1.128610044126608"/>
            <mass value="1.0" />
            <inertia ixx="100" ixy="0" ixz="0" iyy="100" iyz="0" izz="100" />
        </inertial>
        <visual>
            <origin xyz="0.165039395065222 -0.06880540793948373 -0.3485858241632802" rpy="0 -0.3949924188976809 -1.128610044126608"/>
            <geometry>
                <box size="0.7835413528150419 0.5573811368381423 0.4818255872887541" />
            </geometry>
            <material name="0 1 0 1">
                <color rgba="0 1 0 1"/>
            </material>
        </visual>
        <collision>
            <origin xyz="0.165039395065222 -0.06880540793948373 -0.3485858241632802" rpy="0 -0.3949924188976809 -1.128610044126608"/>
            <geometry>
                <box size="0.7835413528150419 0.5573811368381423 0.4818255872887541" />
            </geometry>
        </collision>
    </link>
    <joint name="0_13" type="revolute">
       <parent link="0"/>
       <child  link="13"/>
       <origin rpy="0 0 0" xyz="0.09815735766491679 -0.18147275135556487 2.616903248208219" />
       <axis xyz="0 0 1"/>
       <limit effort="0.0" lower="-3.14159" upper="3.14159" velocity="0.0"/>
    </joint>
    <link name="13">
        <inertial>
            <origin xyz="0.16216489975742834 -0.2998095225091636 0.1931348192126345" rpy="0 -1.0749718594714122 0.872344025037188"/>
            <mass value="1.0" />
            <inertia ixx="100" ixy="0" ixz="0" iyy="100" iyz="0" izz="100" />
        </inertial>
        <visual>
            <origin xyz="0.16216489975742834 -0.2998095225091636 0.1931348192126345" rpy="0 -1.0749718594714122 0.872344025037188"/>
            <geometry>
                <box size="0.7835413528150419 0.5573811368381423 0.4818255872887541" />
            </geometry>
            <material name="0 1 1 1">
                <color rgba="0 1 1 1"/>
            </material>
        </visual>
        <collision>
            <origin xyz="0.16216489975742834 -0.2998095225091636 0.1931348192126345" rpy="0 -1.0749718594714122 0.872344025037188"/>
            <geometry>
                <box size="0.7835413528150419 0.5573811368381423 0.4818255872887541" />
            </geometry>
        </collision>
    </link>
    <joint name="13_14" type="revolute">
       <parent link="13"/>
       <child  link="14"/>
       <origin rpy="0 0 0" xyz="0.2700879089117248 -0.6711090284015964 0.3208373819241639" />
       <axis xyz="0 0 1"/>
       <limit effort="0.0" lower="-3.14159" upper="3.14159" velocity="0.0"/>
    </joint>
    <link name="14">
        <inertial>
            <origin xyz="0.10383153952779316 -0.3572231688573651 0.12286123035195948" rpy="0 -1.287927493636341 0.8691466649299753"/>
            <mass value="1.0" />
            <inertia ixx="100" ixy="0" ixz="0" iyy="100" iyz="0" izz="100" />
        </inertial>
        <visual>
            <origin xyz="0.10383153952779316 -0.3572231688573651 0.12286123035195948" rpy="0 -1.287927493636341 0.8691466649299753"/>
            <geometry>
                <box size="0.7835413528150419 0.5573811368381423 0.4818255872887541" />
            </geometry>
            <material name="0 1 1 1">
                <color rgba="0 1 1 1"/>
            </material>
        </visual>
        <collision>
            <origin xyz="0.10383153952779316 -0.3572231688573651 0.12286123035195948" rpy="0 -1.287927493636341 0.8691466649299753"/>
            <geometry>
                <box size="0.7835413528150419 0.5573811368381423 0.4818255872887541" />
            </geometry>
        </collision>
    </link>
    <joint name="14_15" type="revolute">
       <parent link="14"/>
       <child  link="15"/>
       <origin rpy="0 0 0" xyz="0.14680381618346405 -0.7625523713284654 0.15728545922678855" />
       <axis xyz="0 0 1"/>
       <limit effort="0.0" lower="-3.14159" upper="3.14159" velocity="0.0"/>
    </joint>
    <link name="15">
        <inertial>
            <origin xyz="0.04115683224752396 -0.38820531024679317 0.03296991277432683" rpy="0 -1.4651726689765932 0.6753990964033367"/>
            <mass value="1.0" />
            <inertia ixx="100" ixy="0" ixz="0" iyy="100" iyz="0" izz="100" />
        </inertial>
        <visual>
            <origin xyz="0.04115683224752396 -0.38820531024679317 0.03296991277432683" rpy="0 -1.4651726689765932 0.6753990964033367"/>
            <geometry>
                <box size="0.7835413528150419 0.5573811368381423 0.4818255872887541" />
            </geometry>
            <material name="0 1 1 1">
                <color rgba="0 1 1 1"/>
            </material>
        </visual>
        <collision>
            <origin xyz="0.04115683224752396 -0.38820531024679317 0.03296991277432683" rpy="0 -1.4651726689765932 0.6753990964033367"/>
            <geometry>
                <box size="0.7835413528150419 0.5573811368381423 0.4818255872887541" />
            </geometry>
        </collision>
    </link>
</robot>