<robot name = "robot">
    <link name="0">
        <inertial>
            <origin xyz="0 0 2.5" rpy="0 0 0"/>
            <mass value="1.0" />
            <inertia ixx="100" ixy="0" ixz="0" iyy="100" iyz="0" izz="100" />
        </inertial>
        <visual>
            <origin xyz="0 0 2.5" rpy="0 0 0"/>
            <geometry>
                <box size="0.5427232932533417 0.4981008313001189 0.5682431939992552" />
            </geometry>
            <material name="0 1 1 1">
                <color rgba="0 1 1 1"/>
            </material>
        </visual>
        <collision>
            <origin xyz="0 0 2.5" rpy="0 0 0"/>
            <geometry>
                <box size="0.5427232932533417 0.4981008313001189 0.5682431939992552" />
            </geometry>
        </collision>
    </link>
    <joint name="0_1" type="revolute">
       <parent link="0"/>
       <child  link="1"/>
       <origin rpy="0 0 0" xyz="0.27136164662667084 -0.23026603670960755 2.276264431415631" />
       <axis xyz="0 0 1"/>
       <limit effort="0.0" lower="-3.14159" upper="3.14159" velocity="0.0"/>
    </joint>
    <link name="1">
        <inertial>
            <origin xyz="0.17516911118848738 -0.1486411122895699 -0.1444255707369474" rpy="0 0 0"/>
            <mass value="1.0" />
            <inertia ixx="100" ixy="0" ixz="0" iyy="100" iyz="0" izz="100" />
        </inertial>
        <visual>
            <origin xyz="0.17516911118848738 -0.1486411122895699 -0.1444255707369474" rpy="0 0 0"/>
            <geometry>
                <box size="0.5427232932533417 0.4981008313001189 0.5682431939992552" />
            </geometry>
            <material name="0 1 1 1">
                <color rgba="0 1 1 1"/>
            </material>
        </visual>
        <collision>
            <origin xyz="0.17516911118848738 -0.1486411122895699 -0.1444255707369474" rpy="0 0 0"/>
            <geometry>
                <box size="0.5427232932533417 0.4981008313001189 0.5682431939992552" />
            </geometry>
        </collision>
    </link>
    <joint name="1_2" type="revolute">
       <parent link="1"/>
       <child  link="2"/>
       <origin rpy="0 0 0" xyz="0.21983211039922185 -0.4989462472249149 -0.23958753144456169" />
       <axis xyz="0 0 1"/>
       <limit effort="0.0" lower="-3.14159" upper="3.14159" velocity="0.0"/>
    </joint>
    <link name="2">
        <inertial>
            <origin xyz="0.0331379995526753 -0.2599111481523013 -0.07060602886253795" rpy="0 0 0"/>
            <mass value="1.0" />
            <inertia ixx="100" ixy="0" ixz="0" iyy="100" iyz="0" izz="100" />
        </inertial>
        <visual>
            <origin xyz="0.0331379995526753 -0.2599111481523013 -0.07060602886253795" rpy="0 0 0"/>
            <geometry>
                <box size="0.5427232932533417 0.4981008313001189 0.5682431939992552" />
            </geometry>
            <material name="0 1 0 1">
                <color rgba="0 1 0 1"/>
            </material>
        </visual>
        <collision>
            <origin xyz="0.0331379995526753 -0.2599111481523013 -0.07060602886253795" rpy="0 0 0"/>
            <geometry>
                <box size="0.5427232932533417 0.4981008313001189 0.5682431939992552" />
            </geometry>
        </collision>
    </link>
    <joint name="2_3" type="revolute">
       <parent link="2"/>
       <child  link="3"/>
       <origin rpy="0 0 0" xyz="-0.15412307296302957 -0.6059047221464934 0.07222860771766039" />
       <axis xyz="0 0 1"/>
       <limit effort="0.0" lower="-3.14159" upper="3.14159" velocity="0.0"/>
    </joint>
    <link name="3">
        <inertial>
            <origin xyz="-0.12140979235788667 -0.22432322645313796 0.09260613183373557" rpy="0 0 0"/>
            <mass value="1.0" />
            <inertia ixx="100" ixy="0" ixz="0" iyy="100" iyz="0" izz="100" />
        </inertial>
        <visual>
            <origin xyz="-0.12140979235788667 -0.22432322645313796 0.09260613183373557" rpy="0 0 0"/>
            <geometry>
                <box size="0.5427232932533417 0.4981008313001189 0.5682431939992552" />
            </geometry>
            <material name="0 1 1 1">
                <color rgba="0 1 1 1"/>
            </material>
        </visual>
        <collision>
            <origin xyz="-0.12140979235788667 -0.22432322645313796 0.09260613183373557" rpy="0 0 0"/>
            <geometry>
                <box size="0.5427232932533417 0.4981008313001189 0.5682431939992552" />
            </geometry>
        </collision>
    </link>
    <joint name="3_4" type="revolute">
       <parent link="3"/>
       <child  link="4"/>
       <origin rpy="0 0 0" xyz="-0.42176881740977656 -0.2873151694016384 0.3414024054344654" />
       <axis xyz="0 0 1"/>
       <limit effort="0.0" lower="-3.14159" upper="3.14159" velocity="0.0"/>
    </joint>
    <link name="4">
        <inertial>
            <origin xyz="-0.20630568257978296 -0.04326687298566115 0.17088910526206957" rpy="0 0 0"/>
            <mass value="1.0" />
            <inertia ixx="100" ixy="0" ixz="0" iyy="100" iyz="0" izz="100" />
        </inertial>
        <visual>
            <origin xyz="-0.20630568257978296 -0.04326687298566115 0.17088910526206957" rpy="0 0 0"/>
            <geometry>
                <box size="0.5427232932533417 0.4981008313001189 0.5682431939992552" />
            </geometry>
            <material name="0 1 0 1">
                <color rgba="0 1 0 1"/>
            </material>
        </visual>
        <collision>
            <origin xyz="-0.20630568257978296 -0.04326687298566115 0.17088910526206957" rpy="0 0 0"/>
            <geometry>
                <box size="0.5427232932533417 0.4981008313001189 0.5682431939992552" />
            </geometry>
        </collision>
    </link>
    <joint name="4_5" type="revolute">
       <parent link="4"/>
       <child  link="5"/>
       <origin rpy="0 0 0" xyz="-0.3725077342015399 0.016545400948534697 0.27762140869497487" />
       <axis xyz="0 0 1"/>
       <limit effort="0.0" lower="-3.14159" upper="3.14159" velocity="0.0"/>
    </joint>
    <link name="5">
        <inertial>
            <origin xyz="-0.24986681111897288 0.08992128561519856 0.1604604759203317" rpy="0 0 0"/>
            <mass value="1.0" />
            <inertia ixx="100" ixy="0" ixz="0" iyy="100" iyz="0" izz="100" />
        </inertial>
        <visual>
            <origin xyz="-0.24986681111897288 0.08992128561519856 0.1604604759203317" rpy="0 0 0"/>
            <geometry>
                <box size="0.6205379125824109 0.7529391823669973 0.6900473888648067" />
            </geometry>
            <material name="0 1 1 1">
                <color rgba="0 1 1 1"/>
            </material>
        </visual>
        <collision>
            <origin xyz="-0.24986681111897288 0.08992128561519856 0.1604604759203317" rpy="0 0 0"/>
            <geometry>
                <box size="0.6205379125824109 0.7529391823669973 0.6900473888648067" />
            </geometry>
        </collision>
    </link>
    <joint name="5_6" type="revolute">
       <parent link="5"/>
       <child  link="6"/>
       <origin rpy="0 0 0" xyz="-0.46923313529498634 0.2567732795424311 0.3253042818244062" />
       <axis xyz="0 0 1"/>
       <limit effort="0.0" lower="-3.14159" upper="3.14159" velocity="0.0"/>
    </joint>
    <link name="6">
        <inertial>
            <origin xyz="-0.2119366074778701 0.1612008847606086 0.15926071204538217" rpy="0 0 0"/>
            <mass value="1.0" />
            <inertia ixx="100" ixy="0" ixz="0" iyy="100" iyz="0" izz="100" />
        </inertial>
        <visual>
            <origin xyz="-0.2119366074778701 0.1612008847606086 0.15926071204538217" rpy="0 0 0"/>
            <geometry>
                <box size="0.6205379125824109 0.7529391823669973 0.6900473888648067" />
            </geometry>
            <material name="0 1 1 1">
                <color rgba="0 1 1 1"/>
            </material>
        </visual>
        <collision>
            <origin xyz="-0.2119366074778701 0.1612008847606086 0.15926071204538217" rpy="0 0 0"/>
            <geometry>
                <box size="0.6205379125824109 0.7529391823669973 0.6900473888648067" />
            </geometry>
        </collision>
    </link>
    <joint name="6_7" type="revolute">
       <parent link="6"/>
       <child  link="7"/>
       <origin rpy="0 0 0" xyz="-0.37758195383826326 0.4094525663170668 0.29201235872696285" />
       <axis xyz="0 0 1"/>
       <limit effort="0.0" lower="-3.14159" upper="3.14159" velocity="0.0"/>
    </joint>
    <link name="7">
        <inertial>
            <origin xyz="-0.157345794974278 0.23581319395002356 0.12610021253366294" rpy="0 0 0"/>
            <mass value="1.0" />
            <inertia ixx="100" ixy="0" ixz="0" iyy="100" iyz="0" izz="100" />
        </inertial>
        <visual>
            <origin xyz="-0.157345794974278 0.23581319395002356 0.12610021253366294" rpy="0 0 0"/>
            <geometry>
                <box size="0.6205379125824109 0.7529391823669973 0.6900473888648067" />
            </geometry>
            <material name="0 1 1 1">
                <color rgba="0 1 1 1"/>
            </material>
        </visual>
        <collision>
            <origin xyz="-0.157345794974278 0.23581319395002356 0.12610021253366294" rpy="0 0 0"/>
            <geometry>
                <box size="0.6205379125824109 0.7529391823669973 0.6900473888648067" />
            </geometry>
        </collision>
    </link>
    <joint name="3_8" type="revolute">
       <parent link="3"/>
       <child  link="8"/>
       <origin rpy="0 0 0" xyz="-0.2535718962643009 -0.30919555350194206 0.2530201061107266" />
       <axis xyz="0 0 1"/>
       <limit effort="0.0" lower="-3.14159" upper="3.14159" velocity="0.0"/>
    </joint>
    <link name="8">
        <inertial>
            <origin xyz="-0.18264931043546478 -0.11729437979811826 0.22169366951552302" rpy="0 0 0"/>
            <mass value="1.0" />
            <inertia ixx="100" ixy="0" ixz="0" iyy="100" iyz="0" izz="100" />
        </inertial>
        <visual>
            <origin xyz="-0.18264931043546478 -0.11729437979811826 0.22169366951552302" rpy="0 0 0"/>
            <geometry>
                <box size="0.6205379125824109 0.7529391823669973 0.6900473888648067" />
            </geometry>
            <material name="0 1 1 1">
                <color rgba="0 1 1 1"/>
            </material>
        </visual>
        <collision>
            <origin xyz="-0.18264931043546478 -0.11729437979811826 0.22169366951552302" rpy="0 0 0"/>
            <geometry>
                <box size="0.6205379125824109 0.7529391823669973 0.6900473888648067" />
            </geometry>
        </collision>
    </link>
    <joint name="8_9" type="revolute">
       <parent link="8"/>
       <child  link="9"/>
       <origin rpy="0 0 0" xyz="-0.3085894167097095 -0.17559836943066745 0.5213198226318037" />
       <axis xyz="0 0 1"/>
       <limit effort="0.0" lower="-3.14159" upper="3.14159" velocity="0.0"/>
    </joint>
    <link name="9">
        <inertial>
            <origin xyz="-0.11833609427873686 -0.05478371122666589 0.2815353246275165" rpy="0 0 0"/>
            <mass value="1.0" />
            <inertia ixx="100" ixy="0" ixz="0" iyy="100" iyz="0" izz="100" />
        </inertial>
        <visual>
            <origin xyz="-0.11833609427873686 -0.05478371122666589 0.2815353246275165" rpy="0 0 0"/>
            <geometry>
                <box size="0.6205379125824109 0.7529391823669973 0.6900473888648067" />
            </geometry>
            <material name="0 1 0 1">
                <color rgba="0 1 0 1"/>
            </material>
        </visual>
        <collision>
            <origin xyz="-0.11833609427873686 -0.05478371122666589 0.2815353246275165" rpy="0 0 0"/>
            <geometry>
                <box size="0.6205379125824109 0.7529391823669973 0.6900473888648067" />
            </geometry>
        </collision>
    </link>
    <joint name="9_10" type="revolute">
       <parent link="9"/>
       <child  link="10"/>
       <origin rpy="0 0 0" xyz="-0.1625125288234221 -0.015971530015438447 0.6124544871364147" />
       <axis xyz="0 0 1"/>
       <limit effort="0.0" lower="-3.14159" upper="3.14159" velocity="0.0"/>
    </joint>
    <link name="10">
        <inertial>
            <origin xyz="-0.0407808427854705 0.03582890915597172 0.30548328492477916" rpy="0 0 0"/>
            <mass value="1.0" />
            <inertia ixx="100" ixy="0" ixz="0" iyy="100" iyz="0" izz="100" />
        </inertial>
        <visual>
            <origin xyz="-0.0407808427854705 0.03582890915597172 0.30548328492477916" rpy="0 0 0"/>
            <geometry>
                <box size="0.6205379125824109 0.7529391823669973 0.6900473888648067" />
            </geometry>
            <material name="0 1 1 1">
                <color rgba="0 1 1 1"/>
            </material>
        </visual>
        <collision>
            <origin xyz="-0.0407808427854705 0.03582890915597172 0.30548328492477916" rpy="0 0 0"/>
            <geometry>
                <box size="0.6205379125824109 0.7529391823669973 0.6900473888648067" />
            </geometry>
        </collision>
    </link>
    <joint name="2_11" type="revolute">
       <parent link="2"/>
       <child  link="11"/>
       <origin rpy="0 0 0" xyz="-0.005751957539370495 -0.4771825271163619 0.0036453174887542544" />
       <axis xyz="0 0 1"/>
       <limit effort="0.0" lower="-3.14159" upper="3.14159" velocity="0.0"/>
    </joint>
    <link name="11">
        <inertial>
            <origin xyz="-0.05181384276561154 -0.28947486469235456 0.09892650629248699" rpy="0 0 0"/>
            <mass value="1.0" />
            <inertia ixx="100" ixy="0" ixz="0" iyy="100" iyz="0" izz="100" />
        </inertial>
        <visual>
            <origin xyz="-0.05181384276561154 -0.28947486469235456 0.09892650629248699" rpy="0 0 0"/>
            <geometry>
                <box size="0.6205379125824109 0.7529391823669973 0.6900473888648067" />
            </geometry>
            <material name="0 1 0 1">
                <color rgba="0 1 0 1"/>
            </material>
        </visual>
        <collision>
            <origin xyz="-0.05181384276561154 -0.28947486469235456 0.09892650629248699" rpy="0 0 0"/>
            <geometry>
                <box size="0.6205379125824109 0.7529391823669973 0.6900473888648067" />
            </geometry>
        </collision>
    </link>
    <joint name="11_12" type="revolute">
       <parent link="11"/>
       <child  link="12"/>
       <origin rpy="0 0 0" xyz="-0.01926427514057573 -0.5575295058168593 0.30471829264326605" />
       <axis xyz="0 0 1"/>
       <limit effort="0.0" lower="-3.14159" upper="3.14159" velocity="0.0"/>
    </joint>
    <link name="12">
        <inertial>
            <origin xyz="0.02974668286950555 -0.24497211431763197 0.18807079332805518" rpy="0 0 0"/>
            <mass value="1.0" />
            <inertia ixx="100" ixy="0" ixz="0" iyy="100" iyz="0" izz="100" />
        </inertial>
        <visual>
            <origin xyz="0.02974668286950555 -0.24497211431763197 0.18807079332805518" rpy="0 0 0"/>
            <geometry>
                <box size="0.6205379125824109 0.7529391823669973 0.6900473888648067" />
            </geometry>
            <material name="0 1 1 1">
                <color rgba="0 1 1 1"/>
            </material>
        </visual>
        <collision>
            <origin xyz="0.02974668286950555 -0.24497211431763197 0.18807079332805518" rpy="0 0 0"/>
            <geometry>
                <box size="0.6205379125824109 0.7529391823669973 0.6900473888648067" />
            </geometry>
        </collision>
    </link>
    <joint name="12_13" type="revolute">
       <parent link="12"/>
       <child  link="13"/>
       <origin rpy="0 0 0" xyz="0.14547928680402555 -0.4169471113688586 0.45762400058919467" />
       <axis xyz="0 0 1"/>
       <limit effort="0.0" lower="-3.14159" upper="3.14159" velocity="0.0"/>
    </joint>
    <link name="13">
        <inertial>
            <origin xyz="0.10559949803063141 -0.15691752146788132 0.24595215532718878" rpy="0 0 0"/>
            <mass value="1.0" />
            <inertia ixx="100" ixy="0" ixz="0" iyy="100" iyz="0" izz="100" />
        </inertial>
        <visual>
            <origin xyz="0.10559949803063141 -0.15691752146788132 0.24595215532718878" rpy="0 0 0"/>
            <geometry>
                <box size="0.6205379125824109 0.7529391823669973 0.6900473888648067" />
            </geometry>
            <material name="0 1 0 1">
                <color rgba="0 1 0 1"/>
            </material>
        </visual>
        <collision>
            <origin xyz="0.10559949803063141 -0.15691752146788132 0.24595215532718878" rpy="0 0 0"/>
            <geometry>
                <box size="0.6205379125824109 0.7529391823669973 0.6900473888648067" />
            </geometry>
        </collision>
    </link>
    <joint name="1_14" type="revolute">
       <parent link="1"/>
       <child  link="14"/>
       <origin rpy="0 0 0" xyz="0.25763125412704474 -0.3404412753115185 -0.19279453748644743" />
       <axis xyz="0 0 1"/>
       <limit effort="0.0" lower="-3.14159" upper="3.14159" velocity="0.0"/>
    </joint>
    <link name="14">
        <inertial>
            <origin xyz="0.11938768832891229 -0.27768594494761956 -0.07002800219954916" rpy="0 0 0"/>
            <mass value="1.0" />
            <inertia ixx="100" ixy="0" ixz="0" iyy="100" iyz="0" izz="100" />
        </inertial>
        <visual>
            <origin xyz="0.11938768832891229 -0.27768594494761956 -0.07002800219954916" rpy="0 0 0"/>
            <geometry>
                <box size="0.6205379125824109 0.7529391823669973 0.6900473888648067" />
            </geometry>
            <material name="0 1 0 1">
                <color rgba="0 1 0 1"/>
            </material>
        </visual>
        <collision>
            <origin xyz="0.11938768832891229 -0.27768594494761956 -0.07002800219954916" rpy="0 0 0"/>
            <geometry>
                <box size="0.6205379125824109 0.7529391823669973 0.6900473888648067" />
            </geometry>
        </collision>
    </link>
    <joint name="14_15" type="revolute">
       <parent link="14"/>
       <child  link="15"/>
       <origin rpy="0 0 0" xyz="0.312709673785332 -0.5502197829015657 -0.034438581497460534" />
       <axis xyz="0 0 1"/>
       <limit effort="0.0" lower="-3.14159" upper="3.14159" velocity="0.0"/>
    </joint>
    <link name="15">
        <inertial>
            <origin xyz="0.17850251882291374 -0.2516422352294837 0.032861245573143946" rpy="0 0 0"/>
            <mass value="1.0" />
            <inertia ixx="100" ixy="0" ixz="0" iyy="100" iyz="0" izz="100" />
        </inertial>
        <visual>
            <origin xyz="0.17850251882291374 -0.2516422352294837 0.032861245573143946" rpy="0 0 0"/>
            <geometry>
                <box size="0.6205379125824109 0.7529391823669973 0.6900473888648067" />
            </geometry>
            <material name="0 1 0 1">
                <color rgba="0 1 0 1"/>
            </material>
        </visual>
        <collision>
            <origin xyz="0.17850251882291374 -0.2516422352294837 0.032861245573143946" rpy="0 0 0"/>
            <geometry>
                <box size="0.6205379125824109 0.7529391823669973 0.6900473888648067" />
            </geometry>
        </collision>
    </link>
    <joint name="15_16" type="revolute">
       <parent link="15"/>
       <child  link="16"/>
       <origin rpy="0 0 0" xyz="0.4150643330960989 -0.4511838168276221 0.14931623234022057" />
       <axis xyz="0 0 1"/>
       <limit effort="0.0" lower="-3.14159" upper="3.14159" velocity="0.0"/>
    </joint>
    <link name="16">
        <inertial>
            <origin xyz="0.22196946549738275 -0.18723283108021793 0.10927144453390707" rpy="0 0 0"/>
            <mass value="1.0" />
            <inertia ixx="100" ixy="0" ixz="0" iyy="100" iyz="0" izz="100" />
        </inertial>
        <visual>
            <origin xyz="0.22196946549738275 -0.18723283108021793 0.10927144453390707" rpy="0 0 0"/>
            <geometry>
                <box size="0.6205379125824109 0.7529391823669973 0.6900473888648067" />
            </geometry>
            <material name="0 1 1 1">
                <color rgba="0 1 1 1"/>
            </material>
        </visual>
        <collision>
            <origin xyz="0.22196946549738275 -0.18723283108021793 0.10927144453390707" rpy="0 0 0"/>
            <geometry>
                <box size="0.6205379125824109 0.7529391823669973 0.6900473888648067" />
            </geometry>
        </collision>
    </link>
    <joint name="0_17" type="revolute">
       <parent link="0"/>
       <child  link="17"/>
       <origin rpy="0 0 0" xyz="0.18403457564364956 -0.1295828239932062 2.4377072532280466" />
       <axis xyz="0 0 1"/>
       <limit effort="0.0" lower="-3.14159" upper="3.14159" velocity="0.0"/>
    </joint>
    <link name="17">
        <inertial>
            <origin xyz="0.24449890524422838 -0.17215709870814008 -0.08275895079569036" rpy="0 0 0"/>
            <mass value="1.0" />
            <inertia ixx="100" ixy="0" ixz="0" iyy="100" iyz="0" izz="100" />
        </inertial>
        <visual>
            <origin xyz="0.24449890524422838 -0.17215709870814008 -0.08275895079569036" rpy="0 0 0"/>
            <geometry>
                <box size="0.6205379125824109 0.7529391823669973 0.6900473888648067" />
            </geometry>
            <material name="0 1 0 1">
                <color rgba="0 1 0 1"/>
            </material>
        </visual>
        <collision>
            <origin xyz="0.24449890524422838 -0.17215709870814008 -0.08275895079569036" rpy="0 0 0"/>
            <geometry>
                <box size="0.6205379125824109 0.7529391823669973 0.6900473888648067" />
            </geometry>
        </collision>
    </link>
    <joint name="17_18" type="revolute">
       <parent link="17"/>
       <child  link="18"/>
       <origin rpy="0 0 0" xyz="0.5218905902803808 -0.33559947718370864 -0.08646968220998044" />
       <axis xyz="0 0 1"/>
       <limit effort="0.0" lower="-3.14159" upper="3.14159" velocity="0.0"/>
    </joint>
    <link name="18">
        <inertial>
            <origin xyz="0.2672995603787079 -0.1574959822897215 -0.003575726776359317" rpy="0 0 0"/>
            <mass value="1.0" />
            <inertia ixx="100" ixy="0" ixz="0" iyy="100" iyz="0" izz="100" />
        </inertial>
        <visual>
            <origin xyz="0.2672995603787079 -0.1574959822897215 -0.003575726776359317" rpy="0 0 0"/>
            <geometry>
                <box size="0.6205379125824109 0.7529391823669973 0.6900473888648067" />
            </geometry>
            <material name="0 1 0 1">
                <color rgba="0 1 0 1"/>
            </material>
        </visual>
        <collision>
            <origin xyz="0.2672995603787079 -0.1574959822897215 -0.003575726776359317" rpy="0 0 0"/>
            <geometry>
                <box size="0.6205379125824109 0.7529391823669973 0.6900473888648067" />
            </geometry>
        </collision>
    </link>
    <joint name="18_19" type="revolute">
       <parent link="18"/>
       <child  link="19"/>
       <origin rpy="0 0 0" xyz="0.5569721023189039 -0.2783034453665202 0.0493388143524222" />
       <axis xyz="0 0 1"/>
       <limit effort="0.0" lower="-3.14159" upper="3.14159" velocity="0.0"/>
    </joint>
    <link name="19">
        <inertial>
            <origin xyz="0.2823781764077749 -0.11776535978035102 0.051582077919157206" rpy="0 0 0"/>
            <mass value="1.0" />
            <inertia ixx="100" ixy="0" ixz="0" iyy="100" iyz="0" izz="100" />
        </inertial>
        <visual>
            <origin xyz="0.2823781764077749 -0.11776535978035102 0.051582077919157206" rpy="0 0 0"/>
            <geometry>
                <box size="0.6205379125824109 0.7529391823669973 0.6900473888648067" />
            </geometry>
            <material name="0 1 1 1">
                <color rgba="0 1 1 1"/>
            </material>
        </visual>
        <collision>
            <origin xyz="0.2823781764077749 -0.11776535978035102 0.051582077919157206" rpy="0 0 0"/>
            <geometry>
                <box size="0.6205379125824109 0.7529391823669973 0.6900473888648067" />
            </geometry>
        </collision>
    </link>
</robot>