<robot name = "robot">
    <link name="0">
        <inertial>
            <origin xyz="0 0 2.5" rpy="0 1.5707963267948966 0.0"/>
            <mass value="1.0" />
            <inertia ixx="100" ixy="0" ixz="0" iyy="100" iyz="0" izz="100" />
        </inertial>
        <visual>
            <origin xyz="0 0 2.5" rpy="0 1.5707963267948966 0.0"/>
            <geometry>
                <box size="0.46894964234140124 0.5097757701378711 0.9560491920449294" />
            </geometry>
            <material name="0 1 1 1">
                <color rgba="0 1 1 1"/>
            </material>
        </visual>
        <collision>
            <origin xyz="0 0 2.5" rpy="0 1.5707963267948966 0.0"/>
            <geometry>
                <box size="0.46894964234140124 0.5097757701378711 0.9560491920449294" />
            </geometry>
        </collision>
    </link>
    <joint name="0_1" type="revolute">
       <parent link="0"/>
       <child  link="1"/>
       <origin rpy="0 0 0" xyz="0.23447482117070062 -0.16898551736257744 2.9151729358590712" />
       <axis xyz="0 0 1"/>
       <limit effort="0.0" lower="-3.14159" upper="3.14159" velocity="0.0"/>
    </joint>
    <link name="1">
        <inertial>
            <origin xyz="0.10868125421598418 -0.07832635452968971 0.19243650623299627" rpy="0 1.0566885262766348 -0.6244825466851057"/>
            <mass value="1.0" />
            <inertia ixx="100" ixy="0" ixz="0" iyy="100" iyz="0" izz="100" />
        </inertial>
        <visual>
            <origin xyz="0.10868125421598418 -0.07832635452968971 0.19243650623299627" rpy="0 1.0566885262766348 -0.6244825466851057"/>
            <geometry>
                <box size="0.46894964234140124 0.5097757701378711 0.9560491920449294" />
            </geometry>
            <material name="0 1 1 1">
                <color rgba="0 1 1 1"/>
            </material>
        </visual>
        <collision>
            <origin xyz="0.10868125421598418 -0.07832635452968971 0.19243650623299627" rpy="0 1.0566885262766348 -0.6244825466851057"/>
            <geometry>
                <box size="0.46894964234140124 0.5097757701378711 0.9560491920449294" />
            </geometry>
        </collision>
    </link>
    <joint name="1_2" type="revolute">
       <parent link="1"/>
       <child  link="2"/>
       <origin rpy="0 0 0" xyz="0.5433393389270514 0.04631933006734111 0.28338753411471956" />
       <axis xyz="0 0 1"/>
       <limit effort="0.0" lower="-3.14159" upper="3.14159" velocity="0.0"/>
    </joint>
    <link name="2">
        <inertial>
            <origin xyz="0.22096484708752562 0.06336547186373222 0.04623629624121094" rpy="0 0.20627117113107893 0.2792728427983291"/>
            <mass value="1.0" />
            <inertia ixx="100" ixy="0" ixz="0" iyy="100" iyz="0" izz="100" />
        </inertial>
        <visual>
            <origin xyz="0.22096484708752562 0.06336547186373222 0.04623629624121094" rpy="0 0.20627117113107893 0.2792728427983291"/>
            <geometry>
                <box size="0.46894964234140124 0.5097757701378711 0.9560491920449294" />
            </geometry>
            <material name="0 1 1 1">
                <color rgba="0 1 1 1"/>
            </material>
        </visual>
        <collision>
            <origin xyz="0.22096484708752562 0.06336547186373222 0.04623629624121094" rpy="0 0.20627117113107893 0.2792728427983291"/>
            <geometry>
                <box size="0.46894964234140124 0.5097757701378711 0.9560491920449294" />
            </geometry>
        </collision>
    </link>
    <joint name="2_3" type="revolute">
       <parent link="2"/>
       <child  link="3"/>
       <origin rpy="0 0 0" xyz="0.022949404881734244 0.03680710043344614 0.07160742054311994" />
       <axis xyz="0 0 1"/>
       <limit effort="0.0" lower="-3.14159" upper="3.14159" velocity="0.0"/>
    </joint>
    <link name="3">
        <inertial>
            <origin xyz="-0.42196994056117504 -0.056595759850852974 0.05406574201682948" rpy="0 3.0141599622440256 -3.0082655948631194"/>
            <mass value="1.0" />
            <inertia ixx="100" ixy="0" ixz="0" iyy="100" iyz="0" izz="100" />
        </inertial>
        <visual>
            <origin xyz="-0.42196994056117504 -0.056595759850852974 0.05406574201682948" rpy="0 3.0141599622440256 -3.0082655948631194"/>
            <geometry>
                <box size="0.8583351681717986 0.24226134304531677 0.6073677863107836" />
            </geometry>
            <material name="0 1 1 1">
                <color rgba="0 1 1 1"/>
            </material>
        </visual>
        <collision>
            <origin xyz="-0.42196994056117504 -0.056595759850852974 0.05406574201682948" rpy="0 3.0141599622440256 -3.0082655948631194"/>
            <geometry>
                <box size="0.8583351681717986 0.24226134304531677 0.6073677863107836" />
            </geometry>
        </collision>
    </link>
    <joint name="3_4" type="revolute">
       <parent link="3"/>
       <child  link="4"/>
       <origin rpy="0 0 0" xyz="-0.8525045740063035 -0.07131505059388613 0.08512223063709111" />
       <axis xyz="0 0 1"/>
       <limit effort="0.0" lower="-3.14159" upper="3.14159" velocity="0.0"/>
    </joint>
    <link name="4">
        <inertial>
            <origin xyz="-0.42780670034801505 -0.014626027072088377 0.03085970997202743" rpy="0 3.069582675396133 -3.1074175634728936"/>
            <mass value="1.0" />
            <inertia ixx="100" ixy="0" ixz="0" iyy="100" iyz="0" izz="100" />
        </inertial>
        <visual>
            <origin xyz="-0.42780670034801505 -0.014626027072088377 0.03085970997202743" rpy="0 3.069582675396133 -3.1074175634728936"/>
            <geometry>
                <box size="0.8583351681717986 0.24226134304531677 0.6073677863107836" />
            </geometry>
            <material name="0 1 0 1">
                <color rgba="0 1 0 1"/>
            </material>
        </visual>
        <collision>
            <origin xyz="-0.42780670034801505 -0.014626027072088377 0.03085970997202743" rpy="0 3.069582675396133 -3.1074175634728936"/>
            <geometry>
                <box size="0.8583351681717986 0.24226134304531677 0.6073677863107836" />
            </geometry>
        </collision>
    </link>
    <joint name="4_5" type="revolute">
       <parent link="4"/>
       <child  link="5"/>
       <origin rpy="0 0 0" xyz="-0.8572438621549004 -0.015659115633167575 0.0455588127781177" />
       <axis xyz="0 0 1"/>
       <limit effort="0.0" lower="-3.14159" upper="3.14159" velocity="0.0"/>
    </joint>
    <link name="5">
        <inertial>
            <origin xyz="-0.428915156975663 -0.0010318327842905879 0.0146812352264725" rpy="0 3.1073772488343403 -3.13918697783549"/>
            <mass value="1.0" />
            <inertia ixx="100" ixy="0" ixz="0" iyy="100" iyz="0" izz="100" />
        </inertial>
        <visual>
            <origin xyz="-0.428915156975663 -0.0010318327842905879 0.0146812352264725" rpy="0 3.1073772488343403 -3.13918697783549"/>
            <geometry>
                <box size="0.8583351681717986 0.24226134304531677 0.6073677863107836" />
            </geometry>
            <material name="0 1 1 1">
                <color rgba="0 1 1 1"/>
            </material>
        </visual>
        <collision>
            <origin xyz="-0.428915156975663 -0.0010318327842905879 0.0146812352264725" rpy="0 3.1073772488343403 -3.13918697783549"/>
            <geometry>
                <box size="0.8583351681717986 0.24226134304531677 0.6073677863107836" />
            </geometry>
        </collision>
    </link>
    <joint name="5_6" type="revolute">
       <parent link="5"/>
       <child  link="6"/>
       <origin rpy="0 0 0" xyz="-0.8581331355761083 0.000860128557656045 0.020720968826002436" />
       <axis xyz="0 0 1"/>
       <limit effort="0.0" lower="-3.14159" upper="3.14159" velocity="0.0"/>
    </joint>
    <link name="6">
        <inertial>
            <origin xyz="-0.4291209333537739 0.0018915335736231329 0.006038368028966217" rpy="0 3.127522098971397 3.137184755545142"/>
            <mass value="1.0" />
            <inertia ixx="100" ixy="0" ixz="0" iyy="100" iyz="0" izz="100" />
        </inertial>
        <visual>
            <origin xyz="-0.4291209333537739 0.0018915335736231329 0.006038368028966217" rpy="0 3.127522098971397 3.137184755545142"/>
            <geometry>
                <box size="0.8583351681717986 0.24226134304531677 0.6073677863107836" />
            </geometry>
            <material name="0 1 1 1">
                <color rgba="0 1 1 1"/>
            </material>
        </visual>
        <collision>
            <origin xyz="-0.4291209333537739 0.0018915335736231329 0.006038368028966217" rpy="0 3.127522098971397 3.137184755545142"/>
            <geometry>
                <box size="0.8583351681717986 0.24226134304531677 0.6073677863107836" />
            </geometry>
        </collision>
    </link>
    <joint name="6_7" type="revolute">
       <parent link="6"/>
       <child  link="7"/>
       <origin rpy="0 0 0" xyz="-0.8582978442063155 0.0035963455680038453 0.008157146150785534" />
       <axis xyz="0 0 1"/>
       <limit effort="0.0" lower="-3.14159" upper="3.14159" velocity="0.0"/>
    </joint>
    <link name="7">
        <inertial>
            <origin xyz="-0.4291589684998048 0.0017047407222843354 0.002118689543278693" rpy="0 3.136655852808438 3.137620391838061"/>
            <mass value="1.0" />
            <inertia ixx="100" ixy="0" ixz="0" iyy="100" iyz="0" izz="100" />
        </inertial>
        <visual>
            <origin xyz="-0.4291589684998048 0.0017047407222843354 0.002118689543278693" rpy="0 3.136655852808438 3.137620391838061"/>
            <geometry>
                <box size="0.8583351681717986 0.24226134304531677 0.6073677863107836" />
            </geometry>
            <material name="0 1 1 1">
                <color rgba="0 1 1 1"/>
            </material>
        </visual>
        <collision>
            <origin xyz="-0.4291589684998048 0.0017047407222843354 0.002118689543278693" rpy="0 3.136655852808438 3.137620391838061"/>
            <geometry>
                <box size="0.8583351681717986 0.24226134304531677 0.6073677863107836" />
            </geometry>
        </collision>
    </link>
    <joint name="1_8" type="revolute">
       <parent link="1"/>
       <child  link="8"/>
       <origin rpy="0 0 0" xyz="-0.11991882189824866 -0.13177399831180814 0.06976703255476852" />
       <axis xyz="0 0 1"/>
       <limit effort="0.0" lower="-3.14159" upper="3.14159" velocity="0.0"/>
    </joint>
    <link name="8">
        <inertial>
            <origin xyz="-0.37038289680554026 -0.08659705398155432 -0.19875179301274157" rpy="0 -2.649086447032155 -2.9119142712217956"/>
            <mass value="1.0" />
            <inertia ixx="100" ixy="0" ixz="0" iyy="100" iyz="0" izz="100" />
        </inertial>
        <visual>
            <origin xyz="-0.37038289680554026 -0.08659705398155432 -0.19875179301274157" rpy="0 -2.649086447032155 -2.9119142712217956"/>
            <geometry>
                <box size="0.8583351681717986 0.24226134304531677 0.6073677863107836" />
            </geometry>
            <material name="0 1 1 1">
                <color rgba="0 1 1 1"/>
            </material>
        </visual>
        <collision>
            <origin xyz="-0.37038289680554026 -0.08659705398155432 -0.19875179301274157" rpy="0 -2.649086447032155 -2.9119142712217956"/>
            <geometry>
                <box size="0.8583351681717986 0.24226134304531677 0.6073677863107836" />
            </geometry>
        </collision>
    </link>
    <joint name="8_9" type="revolute">
       <parent link="8"/>
       <child  link="9"/>
       <origin rpy="0 0 0" xyz="-0.8064758475757041 -0.15955855780502728 -0.2809910187045257" />
       <axis xyz="0 0 1"/>
       <limit effort="0.0" lower="-3.14159" upper="3.14159" velocity="0.0"/>
    </joint>
    <link name="9">
        <inertial>
            <origin xyz="-0.4161471922326169 -0.06962443420281249 -0.07847781717769041" rpy="0 -2.955199778079636 -2.9758207897155056"/>
            <mass value="1.0" />
            <inertia ixx="100" ixy="0" ixz="0" iyy="100" iyz="0" izz="100" />
        </inertial>
        <visual>
            <origin xyz="-0.4161471922326169 -0.06962443420281249 -0.07847781717769041" rpy="0 -2.955199778079636 -2.9758207897155056"/>
            <geometry>
                <box size="0.8583351681717986 0.24226134304531677 0.6073677863107836" />
            </geometry>
            <material name="0 1 0 1">
                <color rgba="0 1 0 1"/>
            </material>
        </visual>
        <collision>
            <origin xyz="-0.4161471922326169 -0.06962443420281249 -0.07847781717769041" rpy="0 -2.955199778079636 -2.9758207897155056"/>
            <geometry>
                <box size="0.8583351681717986 0.24226134304531677 0.6073677863107836" />
            </geometry>
        </collision>
    </link>
    <joint name="9_10" type="revolute">
       <parent link="9"/>
       <child  link="10"/>
       <origin rpy="0 0 0" xyz="-0.8476817488425198 -0.11106343801249716 -0.10036621842491456" />
       <axis xyz="0 0 1"/>
       <limit effort="0.0" lower="-3.14159" upper="3.14159" velocity="0.0"/>
    </joint>
    <link name="10">
        <inertial>
            <origin xyz="-0.4266589625828474 -0.04097081474726326 -0.021641100175390796" rpy="0 -3.0909138406521413 -3.0458591118995035"/>
            <mass value="1.0" />
            <inertia ixx="100" ixy="0" ixz="0" iyy="100" iyz="0" izz="100" />
        </inertial>
        <visual>
            <origin xyz="-0.4266589625828474 -0.04097081474726326 -0.021641100175390796" rpy="0 -3.0909138406521413 -3.0458591118995035"/>
            <geometry>
                <box size="0.8583351681717986 0.24226134304531677 0.6073677863107836" />
            </geometry>
            <material name="0 1 1 1">
                <color rgba="0 1 1 1"/>
            </material>
        </visual>
        <collision>
            <origin xyz="-0.4266589625828474 -0.04097081474726326 -0.021641100175390796" rpy="0 -3.0909138406521413 -3.0458591118995035"/>
            <geometry>
                <box size="0.8583351681717986 0.24226134304531677 0.6073677863107836" />
            </geometry>
        </collision>
    </link>
    <joint name="10_11" type="revolute">
       <parent link="10"/>
       <child  link="11"/>
       <origin rpy="0 0 0" xyz="-0.8563194546721674 -0.060900792863968475 -0.023940797081857035" />
       <axis xyz="0 0 1"/>
       <limit effort="0.0" lower="-3.14159" upper="3.14159" velocity="0.0"/>
    </joint>
    <link name="11">
        <inertial>
            <origin xyz="-0.4287005005454299 -0.01988544851527755 -0.002294558687746193" rpy="0 -3.1362403463872193 -3.095240468350669"/>
            <mass value="1.0" />
            <inertia ixx="100" ixy="0" ixz="0" iyy="100" iyz="0" izz="100" />
        </inertial>
        <visual>
            <origin xyz="-0.4287005005454299 -0.01988544851527755 -0.002294558687746193" rpy="0 -3.1362403463872193 -3.095240468350669"/>
            <geometry>
                <box size="0.8583351681717986 0.24226134304531677 0.6073677863107836" />
            </geometry>
            <material name="0 1 1 1">
                <color rgba="0 1 1 1"/>
            </material>
        </visual>
        <collision>
            <origin xyz="-0.4287005005454299 -0.01988544851527755 -0.002294558687746193" rpy="0 -3.1362403463872193 -3.095240468350669"/>
            <geometry>
                <box size="0.8583351681717986 0.24226134304531677 0.6073677863107836" />
            </geometry>
        </collision>
    </link>
    <joint name="11_12" type="revolute">
       <parent link="11"/>
       <child  link="12"/>
       <origin rpy="0 0 0" xyz="-0.8579611929552629 -0.02821294774051402 -9.172658010513004e-05" />
       <axis xyz="0 0 1"/>
       <limit effort="0.0" lower="-3.14159" upper="3.14159" velocity="0.0"/>
    </joint>
    <link name="12">
        <inertial>
            <origin xyz="-0.4290812015879568 -0.008324017169444874 0.002201911016675953" rpy="0 3.136461010254471 -3.1221954552544835"/>
            <mass value="1.0" />
            <inertia ixx="100" ixy="0" ixz="0" iyy="100" iyz="0" izz="100" />
        </inertial>
        <visual>
            <origin xyz="-0.4290812015879568 -0.008324017169444874 0.002201911016675953" rpy="0 3.136461010254471 -3.1221954552544835"/>
            <geometry>
                <box size="0.8583351681717986 0.24226134304531677 0.6073677863107836" />
            </geometry>
            <material name="0 1 1 1">
                <color rgba="0 1 1 1"/>
            </material>
        </visual>
        <collision>
            <origin xyz="-0.4290812015879568 -0.008324017169444874 0.002201911016675953" rpy="0 3.136461010254471 -3.1221954552544835"/>
            <geometry>
                <box size="0.8583351681717986 0.24226134304531677 0.6073677863107836" />
            </geometry>
        </collision>
    </link>
    <joint name="0_13" type="revolute">
       <parent link="0"/>
       <child  link="13"/>
       <origin rpy="0 0 0" xyz="-0.18878047802908102 0.10805825591345074 2.3202930281515037" />
       <axis xyz="0 0 1"/>
       <limit effort="0.0" lower="-3.14159" upper="3.14159" velocity="0.0"/>
    </joint>
    <link name="13">
        <inertial>
            <origin xyz="-0.28714563784857416 0.1643626350723216 -0.2733443287993109" rpy="0 -2.3808131658670884 2.6217133000725013"/>
            <mass value="1.0" />
            <inertia ixx="100" ixy="0" ixz="0" iyy="100" iyz="0" izz="100" />
        </inertial>
        <visual>
            <origin xyz="-0.28714563784857416 0.1643626350723216 -0.2733443287993109" rpy="0 -2.3808131658670884 2.6217133000725013"/>
            <geometry>
                <box size="0.8583351681717986 0.24226134304531677 0.6073677863107836" />
            </geometry>
            <material name="0 1 1 1">
                <color rgba="0 1 1 1"/>
            </material>
        </visual>
        <collision>
            <origin xyz="-0.28714563784857416 0.1643626350723216 -0.2733443287993109" rpy="0 -2.3808131658670884 2.6217133000725013"/>
            <geometry>
                <box size="0.8583351681717986 0.24226134304531677 0.6073677863107836" />
            </geometry>
        </collision>
    </link>
    <joint name="13_14" type="revolute">
       <parent link="13"/>
       <child  link="14"/>
       <origin rpy="0 0 0" xyz="-0.7165176536953131 0.21982595449763065 -0.462762623162023" />
       <axis xyz="0 0 1"/>
       <limit effort="0.0" lower="-3.14159" upper="3.14159" velocity="0.0"/>
    </joint>
    <link name="14">
        <inertial>
            <origin xyz="-0.3899428160378298 0.05037012698850515 -0.17202402668748473" rpy="0 -2.7261210984144646 3.0131308813178745"/>
            <mass value="1.0" />
            <inertia ixx="100" ixy="0" ixz="0" iyy="100" iyz="0" izz="100" />
        </inertial>
        <visual>
            <origin xyz="-0.3899428160378298 0.05037012698850515 -0.17202402668748473" rpy="0 -2.7261210984144646 3.0131308813178745"/>
            <geometry>
                <box size="0.8583351681717986 0.24226134304531677 0.6073677863107836" />
            </geometry>
            <material name="0 1 0 1">
                <color rgba="0 1 0 1"/>
            </material>
        </visual>
        <collision>
            <origin xyz="-0.3899428160378298 0.05037012698850515 -0.17202402668748473" rpy="0 -2.7261210984144646 3.0131308813178745"/>
            <geometry>
                <box size="0.8583351681717986 0.24226134304531677 0.6073677863107836" />
            </geometry>
        </collision>
    </link>
    <joint name="14_15" type="revolute">
       <parent link="14"/>
       <child  link="15"/>
       <origin rpy="0 0 0" xyz="-0.8248040598822698 0.04627151777742495 -0.2581762053774729" />
       <axis xyz="0 0 1"/>
       <limit effort="0.0" lower="-3.14159" upper="3.14159" velocity="0.0"/>
    </joint>
    <link name="15">
        <inertial>
            <origin xyz="-0.42096742960279615 -0.003967658670341255 -0.08339961707596721" rpy="0 -2.946011038159783 -3.132167836105126"/>
            <mass value="1.0" />
            <inertia ixx="100" ixy="0" ixz="0" iyy="100" iyz="0" izz="100" />
        </inertial>
        <visual>
            <origin xyz="-0.42096742960279615 -0.003967658670341255 -0.08339961707596721" rpy="0 -2.946011038159783 -3.132167836105126"/>
            <geometry>
                <box size="0.8583351681717986 0.24226134304531677 0.6073677863107836" />
            </geometry>
            <material name="0 1 0 1">
                <color rgba="0 1 0 1"/>
            </material>
        </visual>
        <collision>
            <origin xyz="-0.42096742960279615 -0.003967658670341255 -0.08339961707596721" rpy="0 -2.946011038159783 -3.132167836105126"/>
            <geometry>
                <box size="0.8583351681717986 0.24226134304531677 0.6073677863107836" />
            </geometry>
        </collision>
    </link>
    <joint name="15_16" type="revolute">
       <parent link="15"/>
       <child  link="16"/>
       <origin rpy="0 0 0" xyz="-0.8516809770968194 -0.01869457814269923 -0.1170929235353374" />
       <axis xyz="0 0 1"/>
       <limit effort="0.0" lower="-3.14159" upper="3.14159" velocity="0.0"/>
    </joint>
    <link name="16">
        <inertial>
            <origin xyz="-0.42761208663625727 -0.014620874597371488 -0.033450689360928675" rpy="0 -3.063524921380227 -3.107414057247664"/>
            <mass value="1.0" />
            <inertia ixx="100" ixy="0" ixz="0" iyy="100" iyz="0" izz="100" />
        </inertial>
        <visual>
            <origin xyz="-0.42761208663625727 -0.014620874597371488 -0.033450689360928675" rpy="0 -3.063524921380227 -3.107414057247664"/>
            <geometry>
                <box size="0.8583351681717986 0.24226134304531677 0.6073677863107836" />
            </geometry>
            <material name="0 1 0 1">
                <color rgba="0 1 0 1"/>
            </material>
        </visual>
        <collision>
            <origin xyz="-0.42761208663625727 -0.014620874597371488 -0.033450689360928675" rpy="0 -3.063524921380227 -3.107414057247664"/>
            <geometry>
                <box size="0.8583351681717986 0.24226134304531677 0.6073677863107836" />
            </geometry>
        </collision>
    </link>
    <joint name="16_17" type="revolute">
       <parent link="16"/>
       <child  link="17"/>
       <origin rpy="0 0 0" xyz="-0.857087376292356 -0.025753077888170404 -0.04460824456816974" />
       <axis xyz="0 0 1"/>
       <limit effort="0.0" lower="-3.14159" upper="3.14159" velocity="0.0"/>
    </joint>
    <link name="17">
        <inertial>
            <origin xyz="-0.42887887301785205 -0.011116743888540191 -0.011142060598521939" rpy="0 -3.115618991576929 -3.1156779818296947"/>
            <mass value="1.0" />
            <inertia ixx="100" ixy="0" ixz="0" iyy="100" iyz="0" izz="100" />
        </inertial>
        <visual>
            <origin xyz="-0.42887887301785205 -0.011116743888540191 -0.011142060598521939" rpy="0 -3.115618991576929 -3.1156779818296947"/>
            <geometry>
                <box size="0.8583351681717986 0.24226134304531677 0.6073677863107836" />
            </geometry>
            <material name="0 1 1 1">
                <color rgba="0 1 1 1"/>
            </material>
        </visual>
        <collision>
            <origin xyz="-0.42887887301785205 -0.011116743888540191 -0.011142060598521939" rpy="0 -3.115618991576929 -3.1156779818296947"/>
            <geometry>
                <box size="0.8583351681717986 0.24226134304531677 0.6073677863107836" />
            </geometry>
        </collision>
    </link>
</robot>